Workbook

Sheet Amortissement
A1: TABLEAU D'AMORTISSEMENT du CAPITAL RESTANT DÛ (CRD)
A4: Capital C₀ (FCFA) | B4: =Paramètres!B5 -> 10000000
A5: Durée n (ans) | B5: =Paramètres!B6 -> 15
A6: Taux débiteur τ | B6: =Paramètres!B7 -> 0.08
A7: Taux mensuel τ_m | B7: =Paramètres!B7/12 -> 0.0066666667
A8: Mensualité m (FCFA) | B8: =Paramètres!B5*(Paramètres!B7/12)/(1-(1+Paramètres!B7/12)^(-12*Paramètres!B6)) -> 95565.208
A10: Année k | B10: Capital Restant Dû en début | C10: Ratio du capital restant dû par rapport au capital initial | D10: Annuité annuelle (FCFA) | E10: Capital remboursé | F10: Intérêts payés | G10: Amortissement %
A11: 0 | B11: =Paramètres!B5 -> 10000000 | C11: =B11/Paramètres!$B$5 -> 1 | D11: =IF(Paramètres!B6>0,12*Paramètres!B5*(Paramètres!B7/12)/(1-(1+Paramètres!B7/12)^(-12*Paramètres!B6)),0) -> 1146782.5 | E11: =Paramètres!B5-B12 -> 359784.71 | F11: =IF(0>=Paramètres!B6,0,D11-E11) -> 786997.79 | G11: =1-B11/Paramètres!$B$5 -> 0
A12: 1 | B12: =IF(1>=Paramètres!B6,0,Paramètres!B5*((1+Paramètres!B7/12)^(12*Paramètres!B6)-(1+Paramètres!B7/12)^(12*1))/((1+Paramètres!B7/12)^(12*Paramètres!B6)-1)) -> 9640215.3 | C12: =B12/Paramètres!$B$5 -> 0.96402153 | D12: =IF(Paramètres!B6>0,12*Paramètres!B5*(Paramètres!B7/12)/(1-(1+Paramètres!B7/12)^(-12*Paramètres!B6)),0) -> 1146782.5 | E12: =IF(1>=Paramètres!B6,0,B12-B13) -> 389646.66 | F12: =IF(1>=Paramètres!B6,0,D12-E12) -> 757135.84 | G12: =1-B12/Paramètres!$B$5 -> 0.035978471
A13: 2 | B13: =IF(2>=Paramètres!B6,0,Paramètres!B5*((1+Paramètres!B7/12)^(12*Paramètres!B6)-(1+Paramètres!B7/12)^(12*2))/((1+Paramètres!B7/12)^(12*Paramètres!B6)-1)) -> 9250568.6 | C13: =B13/Paramètres!$B$5 -> 0.92505686 | D13: =IF(Paramètres!B6>0,12*Paramètres!B5*(Paramètres!B7/12)/(1-(1+Paramètres!B7/12)^(-12*Paramètres!B6)),0) -> 1146782.5 | E13: =IF(2>=Paramètres!B6,0,B13-B14) -> 421987.14 | F13: =IF(2>=Paramètres!B6,0,D13-E13) -> 724795.36 | G13: =1-B13/Paramètres!$B$5 -> 0.074943137
A14: 3 | B14: =IF(3>=Paramètres!B6,0,Paramètres!B5*((1+Paramètres!B7/12)^(12*Paramètres!B6)-(1+Paramètres!B7/12)^(12*3))/((1+Paramètres!B7/12)^(12*Paramètres!B6)-1)) -> 8828581.5 | C14: =B14/Paramètres!$B$5 -> 0.88285815 | D14: =IF(Paramètres!B6>0,12*Paramètres!B5*(Paramètres!B7/12)/(1-(1+Paramètres!B7/12)^(-12*Paramètres!B6)),0) -> 1146782.5 | E14: =IF(3>=Paramètres!B6,0,B14-B15) -> 457011.87 | F14: =IF(3>=Paramètres!B6,0,D14-E14) -> 689770.64 | G14: =1-B14/Paramètres!$B$5 -> 0.11714185
A15: 4 | B15: =IF(4>=Paramètres!B6,0,Paramètres!B5*((1+Paramètres!B7/12)^(12*Paramètres!B6)-(1+Paramètres!B7/12)^(12*4))/((1+Paramètres!B7/12)^(12*Paramètres!B6)-1)) -> 8371569.6 | C15: =B15/Paramètres!$B$5 -> 0.83715696 | D15: =IF(Paramètres!B6>0,12*Paramètres!B5*(Paramètres!B7/12)/(1-(1+Paramètres!B7/12)^(-12*Paramètres!B6)),0) -> 1146782.5 | E15: =IF(4>=Paramètres!B6,0,B15-B16) -> 494943.63 | F15: =IF(4>=Paramètres!B6,0,D15-E15) -> 651838.88 | G15: =1-B15/Paramètres!$B$5 -> 0.16284304
A16: 5 | B16: =IF(5>=Paramètres!B6,0,Paramètres!B5*((1+Paramètres!B7/12)^(12*Paramètres!B6)-(1+Paramètres!B7/12)^(12*5))/((1+Paramètres!B7/12)^(12*Paramètres!B6)-1)) -> 7876626 | C16: =B16/Paramètres!$B$5 -> 0.7876626 | D16: =IF(Paramètres!B6>0,12*Paramètres!B5*(Paramètres!B7/12)/(1-(1+Paramètres!B7/12)^(-12*Paramètres!B6)),0) -> 1146782.5 | E16: =IF(5>=Paramètres!B6,0,B16-B17) -> 536023.7 | F16: =IF(5>=Paramètres!B6,0,D16-E16) -> 610758.8 | G16: =1-B16/Paramètres!$B$5 -> 0.2123374
A17: 6 | B17: =IF(6>=Paramètres!B6,0,Paramètres!B5*((1+Paramètres!B7/12)^(12*Paramètres!B6)-(1+Paramètres!B7/12)^(12*6))/((1+Paramètres!B7/12)^(12*Paramètres!B6)-1)) -> 7340602.3 | C17: =B17/Paramètres!$B$5 -> 0.73406023 | D17: =IF(Paramètres!B6>0,12*Paramètres!B5*(Paramètres!B7/12)/(1-(1+Paramètres!B7/12)^(-12*Paramètres!B6)),0) -> 1146782.5 | E17: =IF(6>=Paramètres!B6,0,B17-B18) -> 580513.4 | F17: =IF(6>=Paramètres!B6,0,D17-E17) -> 566269.1 | G17: =1-B17/Paramètres!$B$5 -> 0.26593977
A18: 7 | B18: =IF(7>=Paramètres!B6,0,Paramètres!B5*((1+Paramètres!B7/12)^(12*Paramètres!B6)-(1+Paramètres!B7/12)^(12*7))/((1+Paramètres!B7/12)^(12*Paramètres!B6)-1)) -> 6760088.9 | C18: =B18/Paramètres!$B$5 -> 0.67600889 | D18: =IF(Paramètres!B6>0,12*Paramètres!B5*(Paramètres!B7/12)/(1-(1+Paramètres!B7/12)^(-12*Paramètres!B6)),0) -> 1146782.5 | E18: =IF(7>=Paramètres!B6,0,B18-B19) -> 628695.73 | F18: =IF(7>=Paramètres!B6,0,D18-E18) -> 518086.77 | G18: =1-B18/Paramètres!$B$5 -> 0.32399111
A19: 8 | B19: =IF(8>=Paramètres!B6,0,Paramètres!B5*((1+Paramètres!B7/12)^(12*Paramètres!B6)-(1+Paramètres!B7/12)^(12*8))/((1+Paramètres!B7/12)^(12*Paramètres!B6)-1)) -> 6131393.2 | C19: =B19/Paramètres!$B$5 -> 0.61313932 | D19: =IF(Paramètres!B6>0,12*Paramètres!B5*(Paramètres!B7/12)/(1-(1+Paramètres!B7/12)^(-12*Paramètres!B6)),0) -> 1146782.5 | E19: =IF(8>=Paramètres!B6,0,B19-B20) -> 680877.17 | F19: =IF(8>=Paramètres!B6,0,D19-E19) -> 465905.33 | G19: =1-B19/Paramètres!$B$5 -> 0.38686068
A20: 9 | B20: =IF(9>=Paramètres!B6,0,Paramètres!B5*((1+Paramètres!B7/12)^(12*Paramètres!B6)-(1+Paramètres!B7/12)^(12*9))/((1+Paramètres!B7/12)^(12*Paramètres!B6)-1)) -> 5450516 | C20: =B20/Paramètres!$B$5 -> 0.5450516 | D20: =IF(Paramètres!B6>0,12*Paramètres!B5*(Paramètres!B7/12)/(1-(1+Paramètres!B7/12)^(-12*Paramètres!B6)),0) -> 1146782.5 | E20: =IF(9>=Paramètres!B6,0,B20-B21) -> 737389.64 | F20: =IF(9>=Paramètres!B6,0,D20-E20) -> 409392.87 | G20: =1-B20/Paramètres!$B$5 -> 0.4549484
A21: 10 | B21: =IF(10>=Paramètres!B6,0,Paramètres!B5*((1+Paramètres!B7/12)^(12*Paramètres!B6)-(1+Paramètres!B7/12)^(12*10))/((1+Paramètres!B7/12)^(12*Paramètres!B6)-1)) -> 4713126.4 | C21: =B21/Paramètres!$B$5 -> 0.47131264 | D21: =IF(Paramètres!B6>0,12*Paramètres!B5*(Paramètres!B7/12)/(1-(1+Paramètres!B7/12)^(-12*Paramètres!B6)),0) -> 1146782.5 | E21: =IF(10>=Paramètres!B6,0,B21-B22) -> 798592.61 | F21: =IF(10>=Paramètres!B6,0,D21-E21) -> 348189.89 | G21: =1-B21/Paramètres!$B$5 -> 0.52868736
A22: 11 | B22: =IF(11>=Paramètres!B6,0,Paramètres!B5*((1+Paramètres!B7/12)^(12*Paramètres!B6)-(1+Paramètres!B7/12)^(12*11))/((1+Paramètres!B7/12)^(12*Paramètres!B6)-1)) -> 3914533.7 | C22: =B22/Paramètres!$B$5 -> 0.39145337 | D22: =IF(Paramètres!B6>0,12*Paramètres!B5*(Paramètres!B7/12)/(1-(1+Paramètres!B7/12)^(-12*Paramètres!B6)),0) -> 1146782.5 | E22: =IF(11>=Paramètres!B6,0,B22-B23) -> 864875.4 | F22: =IF(11>=Paramètres!B6,0,D22-E22) -> 281907.1 | G22: =1-B22/Paramètres!$B$5 -> 0.60854663
A23: 12 | B23: =IF(12>=Paramètres!B6,0,Paramètres!B5*((1+Paramètres!B7/12)^(12*Paramètres!B6)-(1+Paramètres!B7/12)^(12*12))/((1+Paramètres!B7/12)^(12*Paramètres!B6)-1)) -> 3049658.3 | C23: =B23/Paramètres!$B$5 -> 0.30496583 | D23: =IF(Paramètres!B6>0,12*Paramètres!B5*(Paramètres!B7/12)/(1-(1+Paramètres!B7/12)^(-12*Paramètres!B6)),0) -> 1146782.5 | E23: =IF(12>=Paramètres!B6,0,B23-B24) -> 936659.64 | F23: =IF(12>=Paramètres!B6,0,D23-E23) -> 210122.86 | G23: =1-B23/Paramètres!$B$5 -> 0.69503417
A24: 13 | B24: =IF(13>=Paramètres!B6,0,Paramètres!B5*((1+Paramètres!B7/12)^(12*Paramètres!B6)-(1+Paramètres!B7/12)^(12*13))/((1+Paramètres!B7/12)^(12*Paramètres!B6)-1)) -> 2112998.7 | C24: =B24/Paramètres!$B$5 -> 0.21129987 | D24: =IF(Paramètres!B6>0,12*Paramètres!B5*(Paramètres!B7/12)/(1-(1+Paramètres!B7/12)^(-12*Paramètres!B6)),0) -> 1146782.5 | E24: =IF(13>=Paramètres!B6,0,B24-B25) -> 1014401.9 | F24: =IF(13>=Paramètres!B6,0,D24-E24) -> 132380.58 | G24: =1-B24/Paramètres!$B$5 -> 0.78870013
A25: 14 | B25: =IF(14>=Paramètres!B6,0,Paramètres!B5*((1+Paramètres!B7/12)^(12*Paramètres!B6)-(1+Paramètres!B7/12)^(12*14))/((1+Paramètres!B7/12)^(12*Paramètres!B6)-1)) -> 1098596.8 | C25: =B25/Paramètres!$B$5 -> 0.10985968 | D25: =IF(Paramètres!B6>0,12*Paramètres!B5*(Paramètres!B7/12)/(1-(1+Paramètres!B7/12)^(-12*Paramètres!B6)),0) -> 1146782.5 | E25: =IF(14>=Paramètres!B6,0,B25-B26) -> 1098596.8 | F25: =IF(14>=Paramètres!B6,0,D25-E25) -> 48185.717 | G25: =1-B25/Paramètres!$B$5 -> 0.89014032
A26: 15 | B26: =IF(15>=Paramètres!B6,0,Paramètres!B5*((1+Paramètres!B7/12)^(12*Paramètres!B6)-(1+Paramètres!B7/12)^(12*15))/((1+Paramètres!B7/12)^(12*Paramètres!B6)-1)) -> 0 | C26: =B26/Paramètres!$B$5 -> 0 | D26: =IF(Paramètres!B6>0,12*Paramètres!B5*(Paramètres!B7/12)/(1-(1+Paramètres!B7/12)^(-12*Paramètres!B6)),0) -> 1146782.5 | E26: =IF(15>=Paramètres!B6,0,B26-B27) -> 0 | F26: =IF(15>=Paramètres!B6,0,D26-E26) -> 0 | G26: =1-B26/Paramètres!$B$5 -> 1
A27: 16 | B27: =IF(16>=Paramètres!B6,0,Paramètres!B5*((1+Paramètres!B7/12)^(12*Paramètres!B6)-(1+Paramètres!B7/12)^(12*16))/((1+Paramètres!B7/12)^(12*Paramètres!B6)-1)) -> 0 | C27: =B27/Paramètres!$B$5 -> 0 | D27: =IF(Paramètres!B6>0,12*Paramètres!B5*(Paramètres!B7/12)/(1-(1+Paramètres!B7/12)^(-12*Paramètres!B6)),0) -> 1146782.5 | E27: =IF(16>=Paramètres!B6,0,B27-B28) -> 0 | F27: =IF(16>=Paramètres!B6,0,D27-E27) -> 0 | G27: =1-B27/Paramètres!$B$5 -> 1
A28: 17 | B28: =IF(17>=Paramètres!B6,0,Paramètres!B5*((1+Paramètres!B7/12)^(12*Paramètres!B6)-(1+Paramètres!B7/12)^(12*17))/((1+Paramètres!B7/12)^(12*Paramètres!B6)-1)) -> 0 | C28: =B28/Paramètres!$B$5 -> 0 | D28: =IF(Paramètres!B6>0,12*Paramètres!B5*(Paramètres!B7/12)/(1-(1+Paramètres!B7/12)^(-12*Paramètres!B6)),0) -> 1146782.5 | E28: =IF(17>=Paramètres!B6,0,B28-B29) -> 0 | F28: =IF(17>=Paramètres!B6,0,D28-E28) -> 0 | G28: =1-B28/Paramètres!$B$5 -> 1
A29: 18 | B29: =IF(18>=Paramètres!B6,0,Paramètres!B5*((1+Paramètres!B7/12)^(12*Paramètres!B6)-(1+Paramètres!B7/12)^(12*18))/((1+Paramètres!B7/12)^(12*Paramètres!B6)-1)) -> 0 | C29: =B29/Paramètres!$B$5 -> 0 | D29: =IF(Paramètres!B6>0,12*Paramètres!B5*(Paramètres!B7/12)/(1-(1+Paramètres!B7/12)^(-12*Paramètres!B6)),0) -> 1146782.5 | E29: =IF(18>=Paramètres!B6,0,B29-B30) -> 0 | F29: =IF(18>=Paramètres!B6,0,D29-E29) -> 0 | G29: =1-B29/Paramètres!$B$5 -> 1
A30: 19 | B30: =IF(19>=Paramètres!B6,0,Paramètres!B5*((1+Paramètres!B7/12)^(12*Paramètres!B6)-(1+Paramètres!B7/12)^(12*19))/((1+Paramètres!B7/12)^(12*Paramètres!B6)-1)) -> 0 | C30: =B30/Paramètres!$B$5 -> 0 | D30: =IF(Paramètres!B6>0,12*Paramètres!B5*(Paramètres!B7/12)/(1-(1+Paramètres!B7/12)^(-12*Paramètres!B6)),0) -> 1146782.5 | E30: =IF(19>=Paramètres!B6,0,B30-B31) -> 0 | F30: =IF(19>=Paramètres!B6,0,D30-E30) -> 0 | G30: =1-B30/Paramètres!$B$5 -> 1
A31: 20 | B31: =IF(20>=Paramètres!B6,0,Paramètres!B5*((1+Paramètres!B7/12)^(12*Paramètres!B6)-(1+Paramètres!B7/12)^(12*20))/((1+Paramètres!B7/12)^(12*Paramètres!B6)-1)) -> 0 | C31: =B31/Paramètres!$B$5 -> 0 | D31: =IF(Paramètres!B6>0,12*Paramètres!B5*(Paramètres!B7/12)/(1-(1+Paramètres!B7/12)^(-12*Paramètres!B6)),0) -> 1146782.5 | E31: =IF(20>=Paramètres!B6,0,B31-B32) -> 0 | F31: =IF(20>=Paramètres!B6,0,D31-E31) -> 0 | G31: =1-B31/Paramètres!$B$5 -> 1
A32: 21 | B32: =IF(21>=Paramètres!B6,0,Paramètres!B5*((1+Paramètres!B7/12)^(12*Paramètres!B6)-(1+Paramètres!B7/12)^(12*21))/((1+Paramètres!B7/12)^(12*Paramètres!B6)-1)) -> 0 | C32: =B32/Paramètres!$B$5 -> 0 | D32: =IF(Paramètres!B6>0,12*Paramètres!B5*(Paramètres!B7/12)/(1-(1+Paramètres!B7/12)^(-12*Paramètres!B6)),0) -> 1146782.5 | E32: =IF(21>=Paramètres!B6,0,B32-B33) -> 0 | F32: =IF(21>=Paramètres!B6,0,D32-E32) -> 0 | G32: =1-B32/Paramètres!$B$5 -> 1
A33: 22 | B33: =IF(22>=Paramètres!B6,0,Paramètres!B5*((1+Paramètres!B7/12)^(12*Paramètres!B6)-(1+Paramètres!B7/12)^(12*22))/((1+Paramètres!B7/12)^(12*Paramètres!B6)-1)) -> 0 | C33: =B33/Paramètres!$B$5 -> 0 | D33: =IF(Paramètres!B6>0,12*Paramètres!B5*(Paramètres!B7/12)/(1-(1+Paramètres!B7/12)^(-12*Paramètres!B6)),0) -> 1146782.5 | E33: =IF(22>=Paramètres!B6,0,B33-B34) -> 0 | F33: =IF(22>=Paramètres!B6,0,D33-E33) -> 0 | G33: =1-B33/Paramètres!$B$5 -> 1
A34: 23 | B34: =IF(23>=Paramètres!B6,0,Paramètres!B5*((1+Paramètres!B7/12)^(12*Paramètres!B6)-(1+Paramètres!B7/12)^(12*23))/((1+Paramètres!B7/12)^(12*Paramètres!B6)-1)) -> 0 | C34: =B34/Paramètres!$B$5 -> 0 | D34: =IF(Paramètres!B6>0,12*Paramètres!B5*(Paramètres!B7/12)/(1-(1+Paramètres!B7/12)^(-12*Paramètres!B6)),0) -> 1146782.5 | E34: =IF(23>=Paramètres!B6,0,B34-B35) -> 0 | F34: =IF(23>=Paramètres!B6,0,D34-E34) -> 0 | G34: =1-B34/Paramètres!$B$5 -> 1
A35: 24 | B35: =IF(24>=Paramètres!B6,0,Paramètres!B5*((1+Paramètres!B7/12)^(12*Paramètres!B6)-(1+Paramètres!B7/12)^(12*24))/((1+Paramètres!B7/12)^(12*Paramètres!B6)-1)) -> 0 | C35: =B35/Paramètres!$B$5 -> 0 | D35: =IF(Paramètres!B6>0,12*Paramètres!B5*(Paramètres!B7/12)/(1-(1+Paramètres!B7/12)^(-12*Paramètres!B6)),0) -> 1146782.5 | E35: =IF(24>=Paramètres!B6,0,B35-B36) -> 0 | F35: =IF(24>=Paramètres!B6,0,D35-E35) -> 0 | G35: =1-B35/Paramètres!$B$5 -> 1
A36: 25 | B36: =IF(25>=Paramètres!B6,0,Paramètres!B5*((1+Paramètres!B7/12)^(12*Paramètres!B6)-(1+Paramètres!B7/12)^(12*25))/((1+Paramètres!B7/12)^(12*Paramètres!B6)-1)) -> 0 | C36: =B36/Paramètres!$B$5 -> 0 | D36: =IF(Paramètres!B6>0,12*Paramètres!B5*(Paramètres!B7/12)/(1-(1+Paramètres!B7/12)^(-12*Paramètres!B6)),0) -> 1146782.5 | E36: =IF(25>=Paramètres!B6,0,B36-B37) -> 0 | F36: =IF(25>=Paramètres!B6,0,D36-E36) -> 0 | G36: =1-B36/Paramètres!$B$5 -> 1
A37: 26 | B37: =IF(26>=Paramètres!B6,0,Paramètres!B5*((1+Paramètres!B7/12)^(12*Paramètres!B6)-(1+Paramètres!B7/12)^(12*26))/((1+Paramètres!B7/12)^(12*Paramètres!B6)-1)) -> 0 | C37: =B37/Paramètres!$B$5 -> 0 | D37: =IF(Paramètres!B6>0,12*Paramètres!B5*(Paramètres!B7/12)/(1-(1+Paramètres!B7/12)^(-12*Paramètres!B6)),0) -> 1146782.5 | E37: =IF(26>=Paramètres!B6,0,B37-B38) -> 0 | F37: =IF(26>=Paramètres!B6,0,D37-E37) -> 0 | G37: =1-B37/Paramètres!$B$5 -> 1
A38: 27 | B38: =IF(27>=Paramètres!B6,0,Paramètres!B5*((1+Paramètres!B7/12)^(12*Paramètres!B6)-(1+Paramètres!B7/12)^(12*27))/((1+Paramètres!B7/12)^(12*Paramètres!B6)-1)) -> 0 | C38: =B38/Paramètres!$B$5 -> 0 | D38: =IF(Paramètres!B6>0,12*Paramètres!B5*(Paramètres!B7/12)/(1-(1+Paramètres!B7/12)^(-12*Paramètres!B6)),0) -> 1146782.5 | E38: =IF(27>=Paramètres!B6,0,B38-B39) -> 0 | F38: =IF(27>=Paramètres!B6,0,D38-E38) -> 0 | G38: =1-B38/Paramètres!$B$5 -> 1
A39: 28 | B39: =IF(28>=Paramètres!B6,0,Paramètres!B5*((1+Paramètres!B7/12)^(12*Paramètres!B6)-(1+Paramètres!B7/12)^(12*28))/((1+Paramètres!B7/12)^(12*Paramètres!B6)-1)) -> 0 | C39: =B39/Paramètres!$B$5 -> 0 | D39: =IF(Paramètres!B6>0,12*Paramètres!B5*(Paramètres!B7/12)/(1-(1+Paramètres!B7/12)^(-12*Paramètres!B6)),0) -> 1146782.5 | E39: =IF(28>=Paramètres!B6,0,B39-B40) -> 0 | F39: =IF(28>=Paramètres!B6,0,D39-E39) -> 0 | G39: =1-B39/Paramètres!$B$5 -> 1
A40: 29 | B40: =IF(29>=Paramètres!B6,0,Paramètres!B5*((1+Paramètres!B7/12)^(12*Paramètres!B6)-(1+Paramètres!B7/12)^(12*29))/((1+Paramètres!B7/12)^(12*Paramètres!B6)-1)) -> 0 | C40: =B40/Paramètres!$B$5 -> 0 | D40: =IF(Paramètres!B6>0,12*Paramètres!B5*(Paramètres!B7/12)/(1-(1+Paramètres!B7/12)^(-12*Paramètres!B6)),0) -> 1146782.5 | E40: =IF(29>=Paramètres!B6,0,B40-B41) -> 0 | F40: =IF(29>=Paramètres!B6,0,D40-E40) -> 0 | G40: =1-B40/Paramètres!$B$5 -> 1
A41: 30 | B41: =IF(30>=Paramètres!B6,0,Paramètres!B5*((1+Paramètres!B7/12)^(12*Paramètres!B6)-(1+Paramètres!B7/12)^(12*30))/((1+Paramètres!B7/12)^(12*Paramètres!B6)-1)) -> 0 | C41: =B41/Paramètres!$B$5 -> 0 | D41: =IF(Paramètres!B6>0,12*Paramètres!B5*(Paramètres!B7/12)/(1-(1+Paramètres!B7/12)^(-12*Paramètres!B6)),0) -> 1146782.5 | E41: =0 -> 0 | F41: =IF(30>=Paramètres!B6,0,D41-E41) -> 0 | G41: =1-B41/Paramètres!$B$5 -> 1

Sheet Commutation
A1: FONCTIONS DE COMMUTATION - Tables CIMA H et CIMA F - Taux technique i = 3,5%
A4: Âge x | B4: D_x (H) | C4: C_x (H) | D4: M_x (H) | E4: N_x (H) | F4: Âge x | G4: D_x (F) | H4: C_x (F) | I4: M_x (F) | J4: N_x (F)
A5: 20 | B5: =VLOOKUP(A5,Tables_CIMA!$A$5:$D$65,2,FALSE())*POWER(1/(1+Paramètres!$B$8),A5) -> 494214.24 | C5: =VLOOKUP(A5,Tables_CIMA!$A$5:$D$65,3,FALSE())*POWER(1/(1+Paramètres!$B$8),A5+0.5) -> 765.19874 | D5: =SUM(C5:C65) -> 97421.339 | E5: =SUM(B5:B65) -> 11782863 | F5: 20 | G5: =VLOOKUP(F5,Tables_CIMA!$E$5:$H$65,2,FALSE())*POWER(1/(1+Paramètres!$B$8),F5) -> 498122.2 | H5: =VLOOKUP(F5,Tables_CIMA!$E$5:$H$65,3,FALSE())*POWER(1/(1+Paramètres!$B$8),F5+0.5) -> 409.52212 | I5: =SUM(H5:H65) -> 82243.105 | J5: =SUM(G5:G65) -> 12339614
A6: 21 | B6: =VLOOKUP(A6,Tables_CIMA!$A$5:$D$65,2,FALSE())*POWER(1/(1+Paramètres!$B$8),A6) -> 476749.54 | C6: =VLOOKUP(A6,Tables_CIMA!$A$5:$D$65,3,FALSE())*POWER(1/(1+Paramètres!$B$8),A6+0.5) -> 769.39174 | D6: =SUM(C6:C65) -> 96656.141 | E6: =SUM(B6:B65) -> 11288648 | F6: 21 | G6: =VLOOKUP(F6,Tables_CIMA!$E$5:$H$65,2,FALSE())*POWER(1/(1+Paramètres!$B$8),F6) -> 480874.95 | H6: =VLOOKUP(F6,Tables_CIMA!$E$5:$H$65,3,FALSE())*POWER(1/(1+Paramètres!$B$8),F6+0.5) -> 409.03767 | I6: =SUM(H6:H65) -> 81833.583 | J6: =SUM(G6:G65) -> 11841492
A7: 22 | B7: =VLOOKUP(A7,Tables_CIMA!$A$5:$D$65,2,FALSE())*POWER(1/(1+Paramètres!$B$8),A7) -> 459871.3 | C7: =VLOOKUP(A7,Tables_CIMA!$A$5:$D$65,3,FALSE())*POWER(1/(1+Paramètres!$B$8),A7+0.5) -> 767.8146 | D7: =SUM(C7:C65) -> 95886.749 | E7: =SUM(B7:B65) -> 10811899 | F7: 22 | G7: =VLOOKUP(F7,Tables_CIMA!$E$5:$H$65,2,FALSE())*POWER(1/(1+Paramètres!$B$8),F7) -> 464211.41 | H7: =VLOOKUP(F7,Tables_CIMA!$E$5:$H$65,3,FALSE())*POWER(1/(1+Paramètres!$B$8),F7+0.5) -> 412.72917 | I7: =SUM(H7:H65) -> 81424.546 | J7: =SUM(G7:G65) -> 11360617
A8: 23 | B8: =VLOOKUP(A8,Tables_CIMA!$A$5:$D$65,2,FALSE())*POWER(1/(1+Paramètres!$B$8),A8) -> 443565.38 | C8: =VLOOKUP(A8,Tables_CIMA!$A$5:$D$65,3,FALSE())*POWER(1/(1+Paramètres!$B$8),A8+0.5) -> 766.35541 | D8: =SUM(C8:C65) -> 95118.934 | E8: =SUM(B8:B65) -> 10352028 | F8: 23 | G8: =VLOOKUP(F8,Tables_CIMA!$E$5:$H$65,2,FALSE())*POWER(1/(1+Paramètres!$B$8),F8) -> 448107.75 | H8: =VLOOKUP(F8,Tables_CIMA!$E$5:$H$65,3,FALSE())*POWER(1/(1+Paramètres!$B$8),F8+0.5) -> 394.31659 | I8: =SUM(H8:H65) -> 81011.816 | J8: =SUM(G8:G65) -> 10896405
A9: 24 | B9: =VLOOKUP(A9,Tables_CIMA!$A$5:$D$65,2,FALSE())*POWER(1/(1+Paramètres!$B$8),A9) -> 427812.29 | C9: =VLOOKUP(A9,Tables_CIMA!$A$5:$D$65,3,FALSE())*POWER(1/(1+Paramètres!$B$8),A9+0.5) -> 677.58871 | D9: =SUM(C9:C65) -> 94352.579 | E9: =SUM(B9:B65) -> 9908462.2 | F9: 24 | G9: =VLOOKUP(F9,Tables_CIMA!$E$5:$H$65,2,FALSE())*POWER(1/(1+Paramètres!$B$8),F9) -> 432566.76 | H9: =VLOOKUP(F9,Tables_CIMA!$E$5:$H$65,3,FALSE())*POWER(1/(1+Paramètres!$B$8),F9+0.5) -> 388.30052 | I9: =SUM(H9:H65) -> 80617.5 | J9: =SUM(G9:G65) -> 10448298
A10: 25 | B10: =VLOOKUP(A10,Tables_CIMA!$A$5:$D$65,2,FALSE())*POWER(1/(1+Paramètres!$B$8),A10) -> 412679.18 | C10: =VLOOKUP(A10,Tables_CIMA!$A$5:$D$65,3,FALSE())*POWER(1/(1+Paramètres!$B$8),A10+0.5) -> 736.61344 | D10: =SUM(C10:C65) -> 93674.99 | E10: =SUM(B10:B65) -> 9480649.9 | F10: 25 | G10: =VLOOKUP(F10,Tables_CIMA!$E$5:$H$65,2,FALSE())*POWER(1/(1+Paramètres!$B$8),F10) -> 417557.22 | H10: =VLOOKUP(F10,Tables_CIMA!$E$5:$H$65,3,FALSE())*POWER(1/(1+Paramètres!$B$8),F10+0.5) -> 386.81564 | I10: =SUM(H10:H65) -> 80229.199 | J10: =SUM(G10:G65) -> 10015731
A11: 26 | B11: =VLOOKUP(A11,Tables_CIMA!$A$5:$D$65,2,FALSE())*POWER(1/(1+Paramètres!$B$8),A11) -> 397999.79 | C11: =VLOOKUP(A11,Tables_CIMA!$A$5:$D$65,3,FALSE())*POWER(1/(1+Paramètres!$B$8),A11+0.5) -> 724.56351 | D11: =SUM(C11:C65) -> 92938.377 | E11: =SUM(B11:B65) -> 9067970.7 | F11: 26 | G11: =VLOOKUP(F11,Tables_CIMA!$E$5:$H$65,2,FALSE())*POWER(1/(1+Paramètres!$B$8),F11) -> 403056.71 | H11: =VLOOKUP(F11,Tables_CIMA!$E$5:$H$65,3,FALSE())*POWER(1/(1+Paramètres!$B$8),F11+0.5) -> 393.02447 | I11: =SUM(H11:H65) -> 79842.384 | J11: =SUM(G11:G65) -> 9598173.8
A12: 27 | B12: =VLOOKUP(A12,Tables_CIMA!$A$5:$D$65,2,FALSE())*POWER(1/(1+Paramètres!$B$8),A12) -> 383828.66 | C12: =VLOOKUP(A12,Tables_CIMA!$A$5:$D$65,3,FALSE())*POWER(1/(1+Paramètres!$B$8),A12+0.5) -> 714.81584 | D12: =SUM(C12:C65) -> 92213.813 | E12: =SUM(B12:B65) -> 8669970.9 | F12: 27 | G12: =VLOOKUP(F12,Tables_CIMA!$E$5:$H$65,2,FALSE())*POWER(1/(1+Paramètres!$B$8),F12) -> 389040.45 | H12: =VLOOKUP(F12,Tables_CIMA!$E$5:$H$65,3,FALSE())*POWER(1/(1+Paramètres!$B$8),F12+0.5) -> 401.47723 | I12: =SUM(H12:H65) -> 79449.359 | J12: =SUM(G12:G65) -> 9195117.1
A13: 28 | B13: =VLOOKUP(A13,Tables_CIMA!$A$5:$D$65,2,FALSE())*POWER(1/(1+Paramètres!$B$8),A13) -> 370146.32 | C13: =VLOOKUP(A13,Tables_CIMA!$A$5:$D$65,3,FALSE())*POWER(1/(1+Paramètres!$B$8),A13+0.5) -> 708.27518 | D13: =SUM(C13:C65) -> 91498.997 | E13: =SUM(B13:B65) -> 8286142.3 | F13: 28 | G13: =VLOOKUP(F13,Tables_CIMA!$E$5:$H$65,2,FALSE())*POWER(1/(1+Paramètres!$B$8),F13) -> 375489.86 | H13: =VLOOKUP(F13,Tables_CIMA!$E$5:$H$65,3,FALSE())*POWER(1/(1+Paramètres!$B$8),F13+0.5) -> 362.39079 | I13: =SUM(H13:H65) -> 79047.882 | J13: =SUM(G13:G65) -> 8806076.6
A14: 29 | B14: =VLOOKUP(A14,Tables_CIMA!$A$5:$D$65,2,FALSE())*POWER(1/(1+Paramètres!$B$8),A14) -> 356933.1 | C14: =VLOOKUP(A14,Tables_CIMA!$A$5:$D$65,3,FALSE())*POWER(1/(1+Paramètres!$B$8),A14+0.5) -> 608.20731 | D14: =SUM(C14:C65) -> 90790.722 | E14: =SUM(B14:B65) -> 7915995.9 | F14: 29 | G14: =VLOOKUP(F14,Tables_CIMA!$E$5:$H$65,2,FALSE())*POWER(1/(1+Paramètres!$B$8),F14) -> 362435.92 | H14: =VLOOKUP(F14,Tables_CIMA!$E$5:$H$65,3,FALSE())*POWER(1/(1+Paramètres!$B$8),F14+0.5) -> 360.64736 | I14: =SUM(H14:H65) -> 78685.491 | J14: =SUM(G14:G65) -> 8430586.8
A15: 30 | B15: =VLOOKUP(A15,Tables_CIMA!$A$5:$D$65,2,FALSE())*POWER(1/(1+Paramètres!$B$8),A15) -> 344265.06 | C15: =VLOOKUP(A15,Tables_CIMA!$A$5:$D$65,3,FALSE())*POWER(1/(1+Paramètres!$B$8),A15+0.5) -> 674.84036 | D15: =SUM(C15:C65) -> 90182.515 | E15: =SUM(B15:B65) -> 7559062.8 | F15: 30 | G15: =VLOOKUP(F15,Tables_CIMA!$E$5:$H$65,2,FALSE())*POWER(1/(1+Paramètres!$B$8),F15) -> 349825.14 | H15: =VLOOKUP(F15,Tables_CIMA!$E$5:$H$65,3,FALSE())*POWER(1/(1+Paramètres!$B$8),F15+0.5) -> 369.81392 | I15: =SUM(H15:H65) -> 78324.844 | J15: =SUM(G15:G65) -> 8068150.8
A16: 31 | B16: =VLOOKUP(A16,Tables_CIMA!$A$5:$D$65,2,FALSE())*POWER(1/(1+Paramètres!$B$8),A16) -> 331959.91 | C16: =VLOOKUP(A16,Tables_CIMA!$A$5:$D$65,3,FALSE())*POWER(1/(1+Paramètres!$B$8),A16+0.5) -> 664.53899 | D16: =SUM(C16:C65) -> 89507.675 | E16: =SUM(B16:B65) -> 7214797.8 | F16: 31 | G16: =VLOOKUP(F16,Tables_CIMA!$E$5:$H$65,2,FALSE())*POWER(1/(1+Paramètres!$B$8),F16) -> 337631.8 | H16: =VLOOKUP(F16,Tables_CIMA!$E$5:$H$65,3,FALSE())*POWER(1/(1+Paramètres!$B$8),F16+0.5) -> 364.41369 | I16: =SUM(H16:H65) -> 77955.03 | J16: =SUM(G16:G65) -> 7718325.7
A17: 32 | B17: =VLOOKUP(A17,Tables_CIMA!$A$5:$D$65,2,FALSE())*POWER(1/(1+Paramètres!$B$8),A17) -> 320081.01 | C17: =VLOOKUP(A17,Tables_CIMA!$A$5:$D$65,3,FALSE())*POWER(1/(1+Paramètres!$B$8),A17+0.5) -> 662.9894 | D17: =SUM(C17:C65) -> 88843.136 | E17: =SUM(B17:B65) -> 6882837.9 | F17: 32 | G17: =VLOOKUP(F17,Tables_CIMA!$E$5:$H$65,2,FALSE())*POWER(1/(1+Paramètres!$B$8),F17) -> 325856.1 | H17: =VLOOKUP(F17,Tables_CIMA!$E$5:$H$65,3,FALSE())*POWER(1/(1+Paramètres!$B$8),F17+0.5) -> 364.18648 | I17: =SUM(H17:H65) -> 77590.616 | J17: =SUM(G17:G65) -> 7380693.9
A18: 33 | B18: =VLOOKUP(A18,Tables_CIMA!$A$5:$D$65,2,FALSE())*POWER(1/(1+Paramètres!$B$8),A18) -> 308605.33 | C18: =VLOOKUP(A18,Tables_CIMA!$A$5:$D$65,3,FALSE())*POWER(1/(1+Paramètres!$B$8),A18+0.5) -> 668.9971 | D18: =SUM(C18:C65) -> 88180.146 | E18: =SUM(B18:B65) -> 6562756.9 | F18: 33 | G18: =VLOOKUP(F18,Tables_CIMA!$E$5:$H$65,2,FALSE())*POWER(1/(1+Paramètres!$B$8),F18) -> 314478.83 | H18: =VLOOKUP(F18,Tables_CIMA!$E$5:$H$65,3,FALSE())*POWER(1/(1+Paramètres!$B$8),F18+0.5) -> 367.97999 | I18: =SUM(H18:H65) -> 77226.43 | J18: =SUM(G18:G65) -> 7054837.8
A19: 34 | B19: =VLOOKUP(A19,Tables_CIMA!$A$5:$D$65,2,FALSE())*POWER(1/(1+Paramètres!$B$8),A19) -> 297511.81 | C19: =VLOOKUP(A19,Tables_CIMA!$A$5:$D$65,3,FALSE())*POWER(1/(1+Paramètres!$B$8),A19+0.5) -> 684.82686 | D19: =SUM(C19:C65) -> 87511.149 | E19: =SUM(B19:B65) -> 6254151.5 | F19: 34 | G19: =VLOOKUP(F19,Tables_CIMA!$E$5:$H$65,2,FALSE())*POWER(1/(1+Paramètres!$B$8),F19) -> 303482.58 | H19: =VLOOKUP(F19,Tables_CIMA!$E$5:$H$65,3,FALSE())*POWER(1/(1+Paramètres!$B$8),F19+0.5) -> 376.89892 | I19: =SUM(H19:H65) -> 76858.45 | J19: =SUM(G19:G65) -> 6740359
A20: 35 | B20: =VLOOKUP(A20,Tables_CIMA!$A$5:$D$65,2,FALSE())*POWER(1/(1+Paramètres!$B$8),A20) -> 286777.88 | C20: =VLOOKUP(A20,Tables_CIMA!$A$5:$D$65,3,FALSE())*POWER(1/(1+Paramètres!$B$8),A20+0.5) -> 698.23125 | D20: =SUM(C20:C65) -> 86826.322 | E20: =SUM(B20:B65) -> 5956639.7 | F20: 35 | G20: =VLOOKUP(F20,Tables_CIMA!$E$5:$H$65,2,FALSE())*POWER(1/(1+Paramètres!$B$8),F20) -> 292849.41 | H20: =VLOOKUP(F20,Tables_CIMA!$E$5:$H$65,3,FALSE())*POWER(1/(1+Paramètres!$B$8),F20+0.5) -> 385.08869 | I20: =SUM(H20:H65) -> 76481.551 | J20: =SUM(G20:G65) -> 6436876.4
A21: 36 | B21: =VLOOKUP(A21,Tables_CIMA!$A$5:$D$65,2,FALSE())*POWER(1/(1+Paramètres!$B$8),A21) -> 276393.75 | C21: =VLOOKUP(A21,Tables_CIMA!$A$5:$D$65,3,FALSE())*POWER(1/(1+Paramètres!$B$8),A21+0.5) -> 716.78329 | D21: =SUM(C21:C65) -> 86128.091 | E21: =SUM(B21:B65) -> 5669861.8 | F21: 36 | G21: =VLOOKUP(F21,Tables_CIMA!$E$5:$H$65,2,FALSE())*POWER(1/(1+Paramètres!$B$8),F21) -> 282567.77 | H21: =VLOOKUP(F21,Tables_CIMA!$E$5:$H$65,3,FALSE())*POWER(1/(1+Paramètres!$B$8),F21+0.5) -> 395.71223 | I21: =SUM(H21:H65) -> 76096.462 | J21: =SUM(G21:G65) -> 6144027
A22: 37 | B22: =VLOOKUP(A22,Tables_CIMA!$A$5:$D$65,2,FALSE())*POWER(1/(1+Paramètres!$B$8),A22) -> 266342.54 | C22: =VLOOKUP(A22,Tables_CIMA!$A$5:$D$65,3,FALSE())*POWER(1/(1+Paramètres!$B$8),A22+0.5) -> 735.20893 | D22: =SUM(C22:C65) -> 85411.308 | E22: =SUM(B22:B65) -> 5393468.1 | F22: 37 | G22: =VLOOKUP(F22,Tables_CIMA!$E$5:$H$65,2,FALSE())*POWER(1/(1+Paramètres!$B$8),F22) -> 272623.37 | H22: =VLOOKUP(F22,Tables_CIMA!$E$5:$H$65,3,FALSE())*POWER(1/(1+Paramètres!$B$8),F22+0.5) -> 406.27794 | I22: =SUM(H22:H65) -> 75700.75 | J22: =SUM(G22:G65) -> 5861459.2
A23: 38 | B23: =VLOOKUP(A23,Tables_CIMA!$A$5:$D$65,2,FALSE())*POWER(1/(1+Paramètres!$B$8),A23) -> 256613.12 | C23: =VLOOKUP(A23,Tables_CIMA!$A$5:$D$65,3,FALSE())*POWER(1/(1+Paramètres!$B$8),A23+0.5) -> 757.68551 | D23: =SUM(C23:C65) -> 84676.099 | E23: =SUM(B23:B65) -> 5127125.5 | F23: 38 | G23: =VLOOKUP(F23,Tables_CIMA!$E$5:$H$65,2,FALSE())*POWER(1/(1+Paramètres!$B$8),F23) -> 263004.88 | H23: =VLOOKUP(F23,Tables_CIMA!$E$5:$H$65,3,FALSE())*POWER(1/(1+Paramètres!$B$8),F23+0.5) -> 419.39981 | I23: =SUM(H23:H65) -> 75294.472 | J23: =SUM(G23:G65) -> 5588835.8
A24: 39 | B24: =VLOOKUP(A24,Tables_CIMA!$A$5:$D$65,2,FALSE())*POWER(1/(1+Paramètres!$B$8),A24) -> 247190.62 | C24: =VLOOKUP(A24,Tables_CIMA!$A$5:$D$65,3,FALSE())*POWER(1/(1+Paramètres!$B$8),A24+0.5) -> 785.50983 | D24: =SUM(C24:C65) -> 83918.413 | E24: =SUM(B24:B65) -> 4870512.4 | F24: 39 | G24: =VLOOKUP(F24,Tables_CIMA!$E$5:$H$65,2,FALSE())*POWER(1/(1+Paramètres!$B$8),F24) -> 253698.74 | H24: =VLOOKUP(F24,Tables_CIMA!$E$5:$H$65,3,FALSE())*POWER(1/(1+Paramètres!$B$8),F24+0.5) -> 435.79479 | I24: =SUM(H24:H65) -> 74875.072 | J24: =SUM(G24:G65) -> 5325831
A25: 40 | B25: =VLOOKUP(A25,Tables_CIMA!$A$5:$D$65,2,FALSE())*POWER(1/(1+Paramètres!$B$8),A25) -> 238059.4 | C25: =VLOOKUP(A25,Tables_CIMA!$A$5:$D$65,3,FALSE())*POWER(1/(1+Paramètres!$B$8),A25+0.5) -> 818.28207 | D25: =SUM(C25:C65) -> 83132.903 | E25: =SUM(B25:B65) -> 4623321.8 | F25: 40 | G25: =VLOOKUP(F25,Tables_CIMA!$E$5:$H$65,2,FALSE())*POWER(1/(1+Paramètres!$B$8),F25) -> 244691.2 | H25: =VLOOKUP(F25,Tables_CIMA!$E$5:$H$65,3,FALSE())*POWER(1/(1+Paramètres!$B$8),F25+0.5) -> 454.57357 | I25: =SUM(H25:H65) -> 74439.277 | J25: =SUM(G25:G65) -> 5072132.2
A26: 41 | B26: =VLOOKUP(A26,Tables_CIMA!$A$5:$D$65,2,FALSE())*POWER(1/(1+Paramètres!$B$8),A26) -> 229204.76 | C26: =VLOOKUP(A26,Tables_CIMA!$A$5:$D$65,3,FALSE())*POWER(1/(1+Paramètres!$B$8),A26+0.5) -> 859.69319 | D26: =SUM(C26:C65) -> 82314.621 | E26: =SUM(B26:B65) -> 4385262.4 | F26: 41 | G26: =VLOOKUP(F26,Tables_CIMA!$E$5:$H$65,2,FALSE())*POWER(1/(1+Paramètres!$B$8),F26) -> 235969.79 | H26: =VLOOKUP(F26,Tables_CIMA!$E$5:$H$65,3,FALSE())*POWER(1/(1+Paramètres!$B$8),F26+0.5) -> 478.54015 | I26: =SUM(H26:H65) -> 73984.704 | J26: =SUM(G26:G65) -> 4827441
A27: 42 | B27: =VLOOKUP(A27,Tables_CIMA!$A$5:$D$65,2,FALSE())*POWER(1/(1+Paramètres!$B$8),A27) -> 220608.84 | C27: =VLOOKUP(A27,Tables_CIMA!$A$5:$D$65,3,FALSE())*POWER(1/(1+Paramètres!$B$8),A27+0.5) -> 898.52659 | D27: =SUM(C27:C65) -> 81454.928 | E27: =SUM(B27:B65) -> 4156057.6 | F27: 42 | G27: =VLOOKUP(F27,Tables_CIMA!$E$5:$H$65,2,FALSE())*POWER(1/(1+Paramètres!$B$8),F27) -> 227519.76 | H27: =VLOOKUP(F27,Tables_CIMA!$E$5:$H$65,3,FALSE())*POWER(1/(1+Paramètres!$B$8),F27+0.5) -> 501.06126 | I27: =SUM(H27:H65) -> 73506.164 | J27: =SUM(G27:G65) -> 4591471.2
A28: 43 | B28: =VLOOKUP(A28,Tables_CIMA!$A$5:$D$65,2,FALSE())*POWER(1/(1+Paramètres!$B$8),A28) -> 212265.43 | C28: =VLOOKUP(A28,Tables_CIMA!$A$5:$D$65,3,FALSE())*POWER(1/(1+Paramètres!$B$8),A28+0.5) -> 939.12459 | D28: =SUM(C28:C65) -> 80556.402 | E28: =SUM(B28:B65) -> 3935448.8 | F28: 43 | G28: =VLOOKUP(F28,Tables_CIMA!$E$5:$H$65,2,FALSE())*POWER(1/(1+Paramètres!$B$8),F28) -> 219333.34 | H28: =VLOOKUP(F28,Tables_CIMA!$E$5:$H$65,3,FALSE())*POWER(1/(1+Paramètres!$B$8),F28+0.5) -> 524.87077 | I28: =SUM(H28:H65) -> 73005.102 | J28: =SUM(G28:G65) -> 4363951.5
A29: 44 | B29: =VLOOKUP(A29,Tables_CIMA!$A$5:$D$65,2,FALSE())*POWER(1/(1+Paramètres!$B$8),A29) -> 204164.27 | C29: =VLOOKUP(A29,Tables_CIMA!$A$5:$D$65,3,FALSE())*POWER(1/(1+Paramètres!$B$8),A29+0.5) -> 978.5455 | D29: =SUM(C29:C65) -> 79617.277 | E29: =SUM(B29:B65) -> 3723183.4 | F29: 44 | G29: =VLOOKUP(F29,Tables_CIMA!$E$5:$H$65,2,FALSE())*POWER(1/(1+Paramètres!$B$8),F29) -> 211400.35 | H29: =VLOOKUP(F29,Tables_CIMA!$E$5:$H$65,3,FALSE())*POWER(1/(1+Paramètres!$B$8),F29+0.5) -> 548.22779 | I29: =SUM(H29:H65) -> 72480.232 | J29: =SUM(G29:G65) -> 4144618.1
A30: 45 | B30: =VLOOKUP(A30,Tables_CIMA!$A$5:$D$65,2,FALSE())*POWER(1/(1+Paramètres!$B$8),A30) -> 196298.3 | C30: =VLOOKUP(A30,Tables_CIMA!$A$5:$D$65,3,FALSE())*POWER(1/(1+Paramètres!$B$8),A30+0.5) -> 1017.1528 | D30: =SUM(C30:C65) -> 78638.731 | E30: =SUM(B30:B65) -> 3519019.1 | F30: 45 | G30: =VLOOKUP(F30,Tables_CIMA!$E$5:$H$65,2,FALSE())*POWER(1/(1+Paramètres!$B$8),F30) -> 203712.67 | H30: =VLOOKUP(F30,Tables_CIMA!$E$5:$H$65,3,FALSE())*POWER(1/(1+Paramètres!$B$8),F30+0.5) -> 571.28618 | I30: =SUM(H30:H65) -> 71932.004 | J30: =SUM(G30:G65) -> 3933217.8
A31: 46 | B31: =VLOOKUP(A31,Tables_CIMA!$A$5:$D$65,2,FALSE())*POWER(1/(1+Paramètres!$B$8),A31) -> 188660.39 | C31: =VLOOKUP(A31,Tables_CIMA!$A$5:$D$65,3,FALSE())*POWER(1/(1+Paramètres!$B$8),A31+0.5) -> 1050.2122 | D31: =SUM(C31:C65) -> 77621.579 | E31: =SUM(B31:B65) -> 3322720.8 | F31: 46 | G31: =VLOOKUP(F31,Tables_CIMA!$E$5:$H$65,2,FALSE())*POWER(1/(1+Paramètres!$B$8),F31) -> 196262.29 | H31: =VLOOKUP(F31,Tables_CIMA!$E$5:$H$65,3,FALSE())*POWER(1/(1+Paramètres!$B$8),F31+0.5) -> 591.55224 | I31: =SUM(H31:H65) -> 71360.718 | J31: =SUM(G31:G65) -> 3729505.1
A32: 47 | B32: =VLOOKUP(A32,Tables_CIMA!$A$5:$D$65,2,FALSE())*POWER(1/(1+Paramètres!$B$8),A32) -> 181248.27 | C32: =VLOOKUP(A32,Tables_CIMA!$A$5:$D$65,3,FALSE())*POWER(1/(1+Paramètres!$B$8),A32+0.5) -> 1076.1651 | D32: =SUM(C32:C65) -> 76571.366 | E32: =SUM(B32:B65) -> 3134060.4 | F32: 47 | G32: =VLOOKUP(F32,Tables_CIMA!$E$5:$H$65,2,FALSE())*POWER(1/(1+Paramètres!$B$8),F32) -> 189043.94 | H32: =VLOOKUP(F32,Tables_CIMA!$E$5:$H$65,3,FALSE())*POWER(1/(1+Paramètres!$B$8),F32+0.5) -> 607.84302 | I32: =SUM(H32:H65) -> 70769.165 | J32: =SUM(G32:G65) -> 3533242.8
A33: 48 | B33: =VLOOKUP(A33,Tables_CIMA!$A$5:$D$65,2,FALSE())*POWER(1/(1+Paramètres!$B$8),A33) -> 174061.29 | C33: =VLOOKUP(A33,Tables_CIMA!$A$5:$D$65,3,FALSE())*POWER(1/(1+Paramètres!$B$8),A33+0.5) -> 1096.3337 | D33: =SUM(C33:C65) -> 75495.201 | E33: =SUM(B33:B65) -> 2952812.2 | F33: 48 | G33: =VLOOKUP(F33,Tables_CIMA!$E$5:$H$65,2,FALSE())*POWER(1/(1+Paramètres!$B$8),F33) -> 182053.67 | H33: =VLOOKUP(F33,Tables_CIMA!$E$5:$H$65,3,FALSE())*POWER(1/(1+Paramètres!$B$8),F33+0.5) -> 621.03579 | I33: =SUM(H33:H65) -> 70161.322 | J33: =SUM(G33:G65) -> 3344198.9
A34: 49 | B34: =VLOOKUP(A34,Tables_CIMA!$A$5:$D$65,2,FALSE())*POWER(1/(1+Paramètres!$B$8),A34) -> 167097.52 | C34: =VLOOKUP(A34,Tables_CIMA!$A$5:$D$65,3,FALSE())*POWER(1/(1+Paramètres!$B$8),A34+0.5) -> 1112.6324 | D34: =SUM(C34:C65) -> 74398.868 | E34: =SUM(B34:B65) -> 2778750.9 | F34: 49 | G34: =VLOOKUP(F34,Tables_CIMA!$E$5:$H$65,2,FALSE())*POWER(1/(1+Paramètres!$B$8),F34) -> 175286.82 | H34: =VLOOKUP(F34,Tables_CIMA!$E$5:$H$65,3,FALSE())*POWER(1/(1+Paramètres!$B$8),F34+0.5) -> 632.45904 | I34: =SUM(H34:H65) -> 69540.287 | J34: =SUM(G34:G65) -> 3162145.2
A35: 50 | B35: =VLOOKUP(A35,Tables_CIMA!$A$5:$D$65,2,FALSE())*POWER(1/(1+Paramètres!$B$8),A35) -> 160353.22 | C35: =VLOOKUP(A35,Tables_CIMA!$A$5:$D$65,3,FALSE())*POWER(1/(1+Paramètres!$B$8),A35+0.5) -> 1125.5191 | D35: =SUM(C35:C65) -> 73286.235 | E35: =SUM(B35:B65) -> 2611653.3 | F35: 50 | G35: =VLOOKUP(F35,Tables_CIMA!$E$5:$H$65,2,FALSE())*POWER(1/(1+Paramètres!$B$8),F35) -> 168737.57 | H35: =VLOOKUP(F35,Tables_CIMA!$E$5:$H$65,3,FALSE())*POWER(1/(1+Paramètres!$B$8),F35+0.5) -> 641.87151 | I35: =SUM(H35:H65) -> 68907.827 | J35: =SUM(G35:G65) -> 2986858.4
A36: 51 | B36: =VLOOKUP(A36,Tables_CIMA!$A$5:$D$65,2,FALSE())*POWER(1/(1+Paramètres!$B$8),A36) -> 153824.32 | C36: =VLOOKUP(A36,Tables_CIMA!$A$5:$D$65,3,FALSE())*POWER(1/(1+Paramètres!$B$8),A36+0.5) -> 1140.003 | D36: =SUM(C36:C65) -> 72160.716 | E36: =SUM(B36:B65) -> 2451300.1 | F36: 51 | G36: =VLOOKUP(F36,Tables_CIMA!$E$5:$H$65,2,FALSE())*POWER(1/(1+Paramètres!$B$8),F36) -> 162400.55 | H36: =VLOOKUP(F36,Tables_CIMA!$E$5:$H$65,3,FALSE())*POWER(1/(1+Paramètres!$B$8),F36+0.5) -> 652.47486 | I36: =SUM(H36:H65) -> 68265.956 | J36: =SUM(G36:G65) -> 2818120.8
A37: 52 | B37: =VLOOKUP(A37,Tables_CIMA!$A$5:$D$65,2,FALSE())*POWER(1/(1+Paramètres!$B$8),A37) -> 147501.97 | C37: =VLOOKUP(A37,Tables_CIMA!$A$5:$D$65,3,FALSE())*POWER(1/(1+Paramètres!$B$8),A37+0.5) -> 1154.5203 | D37: =SUM(C37:C65) -> 71020.713 | E37: =SUM(B37:B65) -> 2297475.8 | F37: 52 | G37: =VLOOKUP(F37,Tables_CIMA!$E$5:$H$65,2,FALSE())*POWER(1/(1+Paramètres!$B$8),F37) -> 156267.39 | H37: =VLOOKUP(F37,Tables_CIMA!$E$5:$H$65,3,FALSE())*POWER(1/(1+Paramètres!$B$8),F37+0.5) -> 662.94145 | I37: =SUM(H37:H65) -> 67613.481 | J37: =SUM(G37:G65) -> 2655720.3
A38: 53 | B38: =VLOOKUP(A38,Tables_CIMA!$A$5:$D$65,2,FALSE())*POWER(1/(1+Paramètres!$B$8),A38) -> 141379.15 | C38: =VLOOKUP(A38,Tables_CIMA!$A$5:$D$65,3,FALSE())*POWER(1/(1+Paramètres!$B$8),A38+0.5) -> 1168.1809 | D38: =SUM(C38:C65) -> 69866.193 | E38: =SUM(B38:B65) -> 2149973.8 | F38: 53 | G38: =VLOOKUP(F38,Tables_CIMA!$E$5:$H$65,2,FALSE())*POWER(1/(1+Paramètres!$B$8),F38) -> 150331.35 | H38: =VLOOKUP(F38,Tables_CIMA!$E$5:$H$65,3,FALSE())*POWER(1/(1+Paramètres!$B$8),F38+0.5) -> 673.70018 | I38: =SUM(H38:H65) -> 66950.54 | J38: =SUM(G38:G65) -> 2499452.9
A39: 54 | B39: =VLOOKUP(A39,Tables_CIMA!$A$5:$D$65,2,FALSE())*POWER(1/(1+Paramètres!$B$8),A39) -> 135449.95 | C39: =VLOOKUP(A39,Tables_CIMA!$A$5:$D$65,3,FALSE())*POWER(1/(1+Paramètres!$B$8),A39+0.5) -> 1182.6647 | D39: =SUM(C39:C65) -> 68698.012 | E39: =SUM(B39:B65) -> 2008594.7 | F39: 54 | G39: =VLOOKUP(F39,Tables_CIMA!$E$5:$H$65,2,FALSE())*POWER(1/(1+Paramètres!$B$8),F39) -> 144585.47 | H39: =VLOOKUP(F39,Tables_CIMA!$E$5:$H$65,3,FALSE())*POWER(1/(1+Paramètres!$B$8),F39+0.5) -> 684.81364 | I39: =SUM(H39:H65) -> 66276.839 | J39: =SUM(G39:G65) -> 2349121.5
A40: 55 | B40: =VLOOKUP(A40,Tables_CIMA!$A$5:$D$65,2,FALSE())*POWER(1/(1+Paramètres!$B$8),A40) -> 129707.02 | C40: =VLOOKUP(A40,Tables_CIMA!$A$5:$D$65,3,FALSE())*POWER(1/(1+Paramètres!$B$8),A40+0.5) -> 1195.2777 | D40: =SUM(C40:C65) -> 67515.347 | E40: =SUM(B40:B65) -> 1873144.7 | F40: 55 | G40: =VLOOKUP(F40,Tables_CIMA!$E$5:$H$65,2,FALSE())*POWER(1/(1+Paramètres!$B$8),F40) -> 139022.97 | H40: =VLOOKUP(F40,Tables_CIMA!$E$5:$H$65,3,FALSE())*POWER(1/(1+Paramètres!$B$8),F40+0.5) -> 695.14599 | I40: =SUM(H40:H65) -> 65592.026 | J40: =SUM(G40:G65) -> 2204536.1
A41: 56 | B41: =VLOOKUP(A41,Tables_CIMA!$A$5:$D$65,2,FALSE())*POWER(1/(1+Paramètres!$B$8),A41) -> 124145.9 | C41: =VLOOKUP(A41,Tables_CIMA!$A$5:$D$65,3,FALSE())*POWER(1/(1+Paramètres!$B$8),A41+0.5) -> 1206.2578 | D41: =SUM(C41:C65) -> 66320.07 | E41: =SUM(B41:B65) -> 1743437.7 | F41: 56 | G41: =VLOOKUP(F41,Tables_CIMA!$E$5:$H$65,2,FALSE())*POWER(1/(1+Paramètres!$B$8),F41) -> 133638.42 | H41: =VLOOKUP(F41,Tables_CIMA!$E$5:$H$65,3,FALSE())*POWER(1/(1+Paramètres!$B$8),F41+0.5) -> 703.99641 | I41: =SUM(H41:H65) -> 64896.88 | J41: =SUM(G41:G65) -> 2065513.1
A42: 57 | B42: =VLOOKUP(A42,Tables_CIMA!$A$5:$D$65,2,FALSE())*POWER(1/(1+Paramètres!$B$8),A42) -> 118762.05 | C42: =VLOOKUP(A42,Tables_CIMA!$A$5:$D$65,3,FALSE())*POWER(1/(1+Paramètres!$B$8),A42+0.5) -> 1236.847 | D42: =SUM(C42:C65) -> 65113.812 | E42: =SUM(B42:B65) -> 1619291.8 | F42: 57 | G42: =VLOOKUP(F42,Tables_CIMA!$E$5:$H$65,2,FALSE())*POWER(1/(1+Paramètres!$B$8),F42) -> 128427.26 | H42: =VLOOKUP(F42,Tables_CIMA!$E$5:$H$65,3,FALSE())*POWER(1/(1+Paramètres!$B$8),F42+0.5) -> 722.38173 | I42: =SUM(H42:H65) -> 64192.883 | J42: =SUM(G42:G65) -> 1931874.7
...

Sheet Paramètres
A1: SIMULATEUR — ASSURANCE DÉCÈS EMPRUNTEUR SUR DEUX TÊTES (CIMA)
A4: A. PARAMÈTRES DU PRÊT
A5: Capital initial C₀ (FCFA) | B5: 10000000
A6: Durée du prêt n (années) | B6: 15
A7: Taux débiteur τ (annuel %) | B7: 0.08
A8: Taux technique i (%) | B8: 0.035
A10: B. PARAMÈTRES DES ASSURÉS
B11: Assuré 1 (Principal) | C11: Assuré 2 (Co-emprunteur)
A12: Sexe (H=Homme, F=Femme) | B12: H | C12: F
A13: Âge à la souscription | B13: 40 | C13: 38
A14: Quotité αᵢ (%) | B14: 0.7 | C14: 0.3
A16: C. CHARGEMENTS
A17: Chargement inventaire δ (%) | B17: 0.1
A18: Chargement commercial η (%) | B18: 0.25
A19: Frais fixes annuels f (FCFA) | B19: 0

Sheet Tarification
A1: TARIFICATION SUR LES PRIMES ACTUARIELLES (MÉTHODE TABULAIRE CIMA)
A4: Rappel des paramètres clés
A5: C₀ (FCFA) | B5: =Paramètres!B5 -> 10000000
A6: n (ans) | B6: =Paramètres!B6 -> 15
A7: τ débiteur | B7: =Paramètres!B7 -> 0.08
A8: i technique | B8: =Paramètres!B8 -> 0.035
A9: Âge assuré 1 | B9: =Paramètres!B13 -> 40
A10: Âge assuré 2 | B10: =Paramètres!C13 -> 38
A11: Sexe assuré 1 | B11: =Paramètres!B12 -> H
A12: Sexe assuré 2 | B12: =Paramètres!C12 -> F
A13: α₁ quotité 1 | B13: =Paramètres!B14 -> 0.7
A14: α₂ quotité 2 | B14: =Paramètres!C14 -> 0.3
A15: δ chargement inv. | B15: =Paramètres!B17 -> 0.1
A16: η chargement com. | B16: =Paramètres!B18 -> 0.25
A18: RÉSULTATS ACTUARIELS
A19: Composante | B19: Assuré 1 | C19: Assuré 2 | D19: TOTAL
A20: Quotité αᵢ | B20: 70% | C20: 30% | D20: 100%
A21: Prime pure unique PP_i (FCFA) | B21: =Calcul_PP!G23 -> 276706.29 | C21: =Calcul_PP!N23 -> 56403.025 | D21: =Calcul_PP!G24 -> 333109.32
A22: Rente-due ä_{x:n|} | B22: =(VLOOKUP(Paramètres!B13,Commutation!A5:E65,5,FALSE())-VLOOKUP(Paramètres!B13+Paramètres!B6,Commutation!A5:E65,5,FALSE()))/VLOOKUP(Paramètres!B13,Commutation!A5:E65,2,FALSE()) -> 11.552483 | C22: =(VLOOKUP(Paramètres!C13,Commutation!F5:J65,5,FALSE())-VLOOKUP(Paramètres!C13+Paramètres!B6,Commutation!F5:J65,5,FALSE()))/VLOOKUP(Paramètres!C13,Commutation!F5:J65,2,FALSE()) -> 11.746485
A23: Prime annuelle nette PA_i (FCFA/an) | B23: =B21/B22 -> 23952.107 | C23: =C21/C22 -> 4801.6937 | D23: =B23+C23 -> 28753.8
A24: Prime d'inventaire PI_i (FCFA/an) | B24: =(1+Paramètres!B17)*B23 -> 26347.317 | C24: =(1+Paramètres!B17)*C23 -> 5281.863 | D24: =B24+C24 -> 31629.18
A25: Prime commerciale PC_i (FCFA/an) | B25: =B24/(1-Paramètres!B18) -> 35129.756 | C25: =C24/(1-Paramètres!B18) -> 7042.484 | D25: =B25+C25 -> 42172.24
A26: Prime mensuelle (FCFA/mois) | B26: =B25/12 -> 2927.4797 | C26: =C25/12 -> 586.87367 | D26: =D25/12 -> 3514.3534
A27: TAEA global (%) | D27: =D25/Paramètres!B5 -> 0.004217224
A29: Les valeurs ci-dessus sont calculées pour les paramètres par défaut de la feuille Paramètres. Pour la simulation dynamique , veiller consulter Monsieur NDIONE, la feuille Calcul_PP.

Sheet Tableau_de_Bord
A1: TABLEAU DE SYNTHÈSE
A3: RÉSUMÉ DU CONTRAT
A4: Capital assuré C₀ | B4: =Paramètres!B5 -> 10000000 | C4: FCFA
A5: Durée du prêt | B5: =Paramètres!B6 -> 15 | C5: ans
A6: Taux débiteur | B6: =Paramètres!B7 -> 0.08
A7: Assuré 1 : âge / sexe | B7: =Paramètres!B13&" ans / "&Paramètres!B12 -> 40 ans / H
A8: Assuré 2 : âge / sexe | B8: =Paramètres!C13&" ans / "&Paramètres!C12 -> 38 ans / F
A9: Quotité alapha 1 / alapha 2 | B9: =TEXT(Paramètres!B14,"0%")&" / "&TEXT(Paramètres!C14,"0%") -> 70% / 30%
A11: PRIMES
A12: Prime pure unique PP (FCFA) | B12: =Calcul_PP!G24 -> 333109.32
A13: Prime annuelle nette PA (FCFA/an) | B13: =Calcul_PP!G27+Calcul_PP!N27 -> 28753.8
A14: Prime d'inventaire PI (FCFA/an) | B14: =Calcul_PP!G28+Calcul_PP!N28 -> 31629.18
A15: Prime commerciale PC (FCFA/an) | B15: =Calcul_PP!G30 -> 42172.24
A16: Prime mensuelle (FCFA/mois) | B16: =Calcul_PP!G31 -> 3514.3534
A17: TAEA (%) | B17: =Calcul_PP!G32 -> 0.004217224

Sheet Tables_CIMA
A1: TABLES DE MORTALITÉ CIMA H (Hommes) et CIMA F (Femmes),Référence réglementaire CIMA
A2: Source : Tables CIMA réglementaires Cohorte initiale l0 = 1 000 000
A4: Âge x | B4: l_x (H) | C4: d_x (H) | D4: q_x (H) | E4: Âge x | F4: l_x (F) | G4: d_x (F) | H4: q_x (F)
A5: 20 | B5: 983382 | C5: 1549 | D5: 0.0015751763 | E5: 20 | F5: 991158 | G5: 829 | H5: 0.00083639541
A6: 21 | B6: 981833 | C6: 1612 | D6: 0.0016418271 | E6: 21 | F6: 990329 | G6: 857 | H6: 0.00086536898
A7: 22 | B7: 980221 | C7: 1665 | D7: 0.0016985965 | E7: 22 | F7: 989472 | G7: 895 | H7: 0.00090452282
A8: 23 | B8: 978556 | C8: 1720 | D8: 0.0017576919 | E8: 23 | F8: 988577 | G8: 885 | H8: 0.00089522617
A9: 24 | B9: 976836 | C9: 1574 | D9: 0.0016113247 | E9: 24 | F9: 987692 | G9: 902 | H9: 0.00091324016
A10: 25 | B10: 975262 | C10: 1771 | D10: 0.0018159223 | E10: 25 | F10: 986790 | G10: 930 | H10: 0.00094244976
A11: 26 | B11: 973491 | C11: 1803 | D11: 0.0018520972 | E11: 26 | F11: 985860 | G11: 978 | H11: 0.00099202727
A12: 27 | B12: 971688 | C12: 1841 | D12: 0.0018946411 | E12: 27 | F12: 984882 | G12: 1034 | H12: 0.001049872
A13: 28 | B13: 969847 | C13: 1888 | D13: 0.0019466988 | E13: 28 | F13: 983848 | G13: 966 | H13: 0.00098185899
A14: 29 | B14: 967959 | C14: 1678 | D14: 0.0017335445 | E14: 29 | F14: 982882 | G14: 995 | H14: 0.001012329
A15: 30 | B15: 966281 | C15: 1927 | D15: 0.0019942439 | E15: 30 | F15: 981887 | G15: 1056 | H15: 0.0010754802
A16: 31 | B16: 964354 | C16: 1964 | D16: 0.0020365965 | E16: 31 | F16: 980831 | G16: 1077 | H16: 0.0010980485
... A65: 80 | B65: 384899 | C65: 384899 | D65: 1 | E65: 80 | F65: 646754 | G65: 646754 | H65: 1

Sheet Calcul_PP
A1: CALCUL EXHAUSTIF DES PRIMES PURES ANNÉE PAR ANNÉE
A3: Assuré 1 | H3: Assuré 2
A4: k | B4: CRD_k | C4: Âge x1+k | D4: ℓ_{x₁+k} (H) | E4: d_{x1+k} (H) | F4: v^(k+0,5) | G4: phi_k^(1) | H4: k | I4: CRD_k | J4: Âge x₂+k | K4: ℓ_{x₂+k} (F) | L4: d_{x₂+k} (F) | M4: v^(k+0.5) | N4: φ_k^(2)
A5: 0 | B5: =Amortissement!B11 -> 10000000 | C5: =Paramètres!B13+0 -> 40 | D5: =VLOOKUP(C5,Tables_CIMA!$A$5:$D$65,2,FALSE()) -> 942539 | E5: =VLOOKUP(C5,Tables_CIMA!$A$5:$D$65,3,FALSE()) -> 3296 | F5: =(1/(1+Paramètres!$B$8))^(0+0.5) -> 0.98294637 | G5: =IF(0<Paramètres!$B$6,B5*E5*F5/VLOOKUP(Paramètres!$B$13,Tables_CIMA!$A$5:$D$65,2,FALSE()),0) -> 34373.021 | H5: 0 | I5: =Amortissement!B11 -> 10000000 | J5: =Paramètres!C13+0 -> 38 | K5: =VLOOKUP(J5,Tables_CIMA!$E$5:$H$65,2,FALSE()) -> 972069 | L5: =VLOOKUP(J5,Tables_CIMA!$E$5:$H$65,3,FALSE()) -> 1577 | M5: =(1/(1+Paramètres!$B$8))^(0+0.5) -> 0.98294637 | N5: =IF(0<Paramètres!$B$6,I5*L5*M5/VLOOKUP(Paramètres!$C$13,Tables_CIMA!$E$5:$H$65,2,FALSE()),0) -> 15946.465
A6: 1 | B6: =Amortissement!B12 -> 9640215.3 | C6: =Paramètres!B13+1 -> 41 | D6: =VLOOKUP(C6,Tables_CIMA!$A$5:$D$65,2,FALSE()) -> 939243 | E6: =VLOOKUP(C6,Tables_CIMA!$A$5:$D$65,3,FALSE()) -> 3584 | F6: =(1/(1+Paramètres!$B$8))^(1+0.5) -> 0.94970664 | G6: =IF(1<Paramètres!$B$6,B6*E6*F6/VLOOKUP(Paramètres!$B$13,Tables_CIMA!$A$5:$D$65,2,FALSE()),0) -> 34813.275 | H6: 1 | I6: =Amortissement!B12 -> 9640215.3 | J6: =Paramètres!C13+1 -> 39 | K6: =VLOOKUP(J6,Tables_CIMA!$E$5:$H$65,2,FALSE()) -> 970492 | L6: =VLOOKUP(J6,Tables_CIMA!$E$5:$H$65,3,FALSE()) -> 1696 | M6: =(1/(1+Paramètres!$B$8))^(1+0.5) -> 0.94970664 | N6: =IF(1<Paramètres!$B$6,I6*L6*M6/VLOOKUP(Paramètres!$C$13,Tables_CIMA!$E$5:$H$65,2,FALSE()),0) -> 15973.679
A7: 2 | B7: =Amortissement!B13 -> 9250568.6 | C7: =Paramètres!B13+2 -> 42 | D7: =VLOOKUP(C7,Tables_CIMA!$A$5:$D$65,2,FALSE()) -> 935659 | E7: =VLOOKUP(C7,Tables_CIMA!$A$5:$D$65,3,FALSE()) -> 3877 | F7: =(1/(1+Paramètres!$B$8))^(2+0.5) -> 0.91759096 | G7: =IF(2<Paramètres!$B$6,B7*E7*F7/VLOOKUP(Paramètres!$B$13,Tables_CIMA!$A$5:$D$65,2,FALSE()),0) -> 34915.159 | H7: 2 | I7: =Amortissement!B13 -> 9250568.6 | J7: =Paramètres!C13+2 -> 40 | K7: =VLOOKUP(J7,Tables_CIMA!$E$5:$H$65,2,FALSE()) -> 968796 | L7: =VLOOKUP(J7,Tables_CIMA!$E$5:$H$65,3,FALSE()) -> 1831 | M7: =(1/(1+Paramètres!$B$8))^(2+0.5) -> 0.91759096 | N7: =IF(2<Paramètres!$B$6,I7*L7*M7/VLOOKUP(Paramètres!$C$13,Tables_CIMA!$E$5:$H$65,2,FALSE()),0) -> 15988.54
A8: 3 | B8: =Amortissement!B14 -> 8828581.5 | C8: =Paramètres!B13+3 -> 43 | D8: =VLOOKUP(C8,Tables_CIMA!$A$5:$D$65,2,FALSE()) -> 931782 | E8: =VLOOKUP(C8,Tables_CIMA!$A$5:$D$65,3,FALSE()) -> 4194 | F8: =(1/(1+Paramètres!$B$8))^(3+0.5) -> 0.88656131 | G8: =IF(3<Paramètres!$B$6,B8*E8*F8/VLOOKUP(Paramètres!$B$13,Tables_CIMA!$A$5:$D$65,2,FALSE()),0) -> 34828.021 | H8: 3 | I8: =Amortissement!B14 -> 8828581.5 | J8: =Paramètres!C13+3 -> 41 | K8: =VLOOKUP(J8,Tables_CIMA!$E$5:$H$65,2,FALSE()) -> 966965 | L8: =VLOOKUP(J8,Tables_CIMA!$E$5:$H$65,3,FALSE()) -> 1995 | M8: =(1/(1+Paramètres!$B$8))^(3+0.5) -> 0.88656131 | N8: =IF(3<Paramètres!$B$6,I8*L8*M8/VLOOKUP(Paramètres!$C$13,Tables_CIMA!$E$5:$H$65,2,FALSE()),0) -> 16063.697
A9: 4 | B9: =Amortissement!B15 -> 8371569.6 | C9: =Paramètres!B13+4 -> 44 | D9: =VLOOKUP(C9,Tables_CIMA!$A$5:$D$65,2,FALSE()) -> 927588 | E9: =VLOOKUP(C9,Tables_CIMA!$A$5:$D$65,3,FALSE()) -> 4523 | F9: =(1/(1+Paramètres!$B$8))^(4+0.5) -> 0.85658098 | G9: =IF(4<Paramètres!$B$6,B9*E9*F9/VLOOKUP(Paramètres!$B$13,Tables_CIMA!$A$5:$D$65,2,FALSE()),0) -> 34411.419 | H9: 4 | I9: =Amortissement!B15 -> 8371569.6 | J9: =Paramètres!C13+4 -> 42 | K9: =VLOOKUP(J9,Tables_CIMA!$E$5:$H$65,2,FALSE()) -> 964970 | L9: =VLOOKUP(J9,Tables_CIMA!$E$5:$H$65,3,FALSE()) -> 2162 | M9: =(1/(1+Paramètres!$B$8))^(4+0.5) -> 0.85658098 | N9: =IF(4<Paramètres!$B$6,I9*L9*M9/VLOOKUP(Paramètres!$C$13,Tables_CIMA!$E$5:$H$65,2,FALSE()),0) -> 15949.017
A10: 5 | B10: =Amortissement!B16 -> 7876626 | C10: =Paramètres!B13+5 -> 45 | D10: =VLOOKUP(C10,Tables_CIMA!$A$5:$D$65,2,FALSE()) -> 923065 | E10: =VLOOKUP(C10,Tables_CIMA!$A$5:$D$65,3,FALSE()) -> 4866 | F10: =(1/(1+Paramètres!$B$8))^(5+0.5) -> 0.82761447 | G10: =IF(5<Paramètres!$B$6,B10*E10*F10/VLOOKUP(Paramètres!$B$13,Tables_CIMA!$A$5:$D$65,2,FALSE()),0) -> 33654.34 | H10: 5 | I10: =Amortissement!B16 -> 7876626 | J10: =Paramètres!C13+5 -> 43 | K10: =VLOOKUP(J10,Tables_CIMA!$E$5:$H$65,2,FALSE()) -> 962808 | L10: =VLOOKUP(J10,Tables_CIMA!$E$5:$H$65,3,FALSE()) -> 2344 | M10: =(1/(1+Paramètres!$B$8))^(5+0.5) -> 0.82761447 | N10: =IF(5<Paramètres!$B$6,I10*L10*M10/VLOOKUP(Paramètres!$C$13,Tables_CIMA!$E$5:$H$65,2,FALSE()),0) -> 15719.141
A11: 6 | B11: =Amortissement!B17 -> 7340602.3 | C11: =Paramètres!B13+6 -> 46 | D11: =VLOOKUP(C11,Tables_CIMA!$A$5:$D$65,2,FALSE()) -> 918199 | E11: =VLOOKUP(C11,Tables_CIMA!$A$5:$D$65,3,FALSE()) -> 5200 | F11: =(1/(1+Paramètres!$B$8))^(6+0.5) -> 0.79962751 | G11: =IF(6<Paramètres!$B$6,B11*E11*F11/VLOOKUP(Paramètres!$B$13,Tables_CIMA!$A$5:$D$65,2,FALSE()),0) -> 32383.474 | H11: 6 | I11: =Amortissement!B17 -> 7340602.3 | J11: =Paramètres!C13+6 -> 44 | K11: =VLOOKUP(J11,Tables_CIMA!$E$5:$H$65,2,FALSE()) -> 960464 | L11: =VLOOKUP(J11,Tables_CIMA!$E$5:$H$65,3,FALSE()) -> 2534 | M11: =(1/(1+Paramètres!$B$8))^(6+0.5) -> 0.79962751 | N11: =IF(6<Paramètres!$B$6,I11*L11*M11/VLOOKUP(Paramètres!$C$13,Tables_CIMA!$E$5:$H$65,2,FALSE()),0) -> 15301.321
A12: 7 | B12: =Amortissement!B18 -> 6760088.9 | C12: =Paramètres!B13+7 -> 47 | D12: =VLOOKUP(C12,Tables_CIMA!$A$5:$D$65,2,FALSE()) -> 912999 | E12: =VLOOKUP(C12,Tables_CIMA!$A$5:$D$65,3,FALSE()) -> 5515 | F12: =(1/(1+Paramètres!$B$8))^(7+0.5) -> 0.77258697 | G12: =IF(7<Paramètres!$B$6,B12*E12*F12/VLOOKUP(Paramètres!$B$13,Tables_CIMA!$A$5:$D$65,2,FALSE()),0) -> 30559.481 | H12: 7 | I12: =Amortissement!B18 -> 6760088.9 | J12: =Paramètres!C13+7 -> 45 | K12: =VLOOKUP(J12,Tables_CIMA!$E$5:$H$65,2,FALSE()) -> 957930 | L12: =VLOOKUP(J12,Tables_CIMA!$E$5:$H$65,3,FALSE()) -> 2733 | M12: =(1/(1+Paramètres!$B$8))^(7+0.5) -> 0.77258697 | N12: =IF(7<Paramètres!$B$6,I12*L12*M12/VLOOKUP(Paramètres!$C$13,Tables_CIMA!$E$5:$H$65,2,FALSE()),0) -> 14683.931
A13: 8 | B13: =Amortissement!B19 -> 6131393.2 | C13: =Paramètres!B13+8 -> 48 | D13: =VLOOKUP(C13,Tables_CIMA!$A$5:$D$65,2,FALSE()) -> 907484 | E13: =VLOOKUP(C13,Tables_CIMA!$A$5:$D$65,3,FALSE()) -> 5815 | F13: =(1/(1+Paramètres!$B$8))^(8+0.5) -> 0.74646084 | G13: =IF(8<Paramètres!$B$6,B13*E13*F13/VLOOKUP(Paramètres!$B$13,Tables_CIMA!$A$5:$D$65,2,FALSE()),0) -> 28236.872 | H13: 8 | I13: =Amortissement!B19 -> 6131393.2 | J13: =Paramètres!C13+8 -> 46 | K13: =VLOOKUP(J13,Tables_CIMA!$E$5:$H$65,2,FALSE()) -> 955197 | L13: =VLOOKUP(J13,Tables_CIMA!$E$5:$H$65,3,FALSE()) -> 2929 | M13: =(1/(1+Paramètres!$B$8))^(8+0.5) -> 0.74646084 | N13: =IF(8<Paramètres!$B$6,I13*L13*M13/VLOOKUP(Paramètres!$C$13,Tables_CIMA!$E$5:$H$65,2,FALSE()),0) -> 13790.769
A14: 9 | B14: =Amortissement!B20 -> 5450516 | C14: =Paramètres!B13+9 -> 49 | D14: =VLOOKUP(C14,Tables_CIMA!$A$5:$D$65,2,FALSE()) -> 901669 | E14: =VLOOKUP(C14,Tables_CIMA!$A$5:$D$65,3,FALSE()) -> 6108 | F14: =(1/(1+Paramètres!$B$8))^(9+0.5) -> 0.7212182 | G14: =IF(9<Paramètres!$B$6,B14*E14*F14/VLOOKUP(Paramètres!$B$13,Tables_CIMA!$A$5:$D$65,2,FALSE()),0) -> 25474.402 | H14: 9 | I14: =Amortissement!B20 -> 5450516 | J14: =Paramètres!C13+9 -> 47 | K14: =VLOOKUP(J14,Tables_CIMA!$E$5:$H$65,2,FALSE()) -> 952268 | L14: =VLOOKUP(J14,Tables_CIMA!$E$5:$H$65,3,FALSE()) -> 3115 | M14: =(1/(1+Paramètres!$B$8))^(9+0.5) -> 0.7212182 | N14: =IF(9<Paramètres!$B$6,I14*L14*M14/VLOOKUP(Paramètres!$C$13,Tables_CIMA!$E$5:$H$65,2,FALSE()),0) -> 12596.946
A15: 10 | B15: =Amortissement!B21 -> 4713126.4 | C15: =Paramètres!B13+10 -> 50 | D15: =VLOOKUP(C15,Tables_CIMA!$A$5:$D$65,2,FALSE()) -> 895561 | E15: =VLOOKUP(C15,Tables_CIMA!$A$5:$D$65,3,FALSE()) -> 6395 | F15: =(1/(1+Paramètres!$B$8))^(10+0.5) -> 0.69682918 | G15: =IF(10<Paramètres!$B$6,B15*E15*F15/VLOOKUP(Paramètres!$B$13,Tables_CIMA!$A$5:$D$65,2,FALSE()),0) -> 22283.152 | H15: 10 | I15: =Amortissement!B21 -> 4713126.4 | J15: =Paramètres!C13+10 -> 48 | K15: =VLOOKUP(J15,Tables_CIMA!$E$5:$H$65,2,FALSE()) -> 949153 | L15: =VLOOKUP(J15,Tables_CIMA!$E$5:$H$65,3,FALSE()) -> 3294 | M15: =(1/(1+Paramètres!$B$8))^(10+0.5) -> 0.69682918 | N15: =IF(10<Paramètres!$B$6,I15*L15*M15/VLOOKUP(Paramètres!$C$13,Tables_CIMA!$E$5:$H$65,2,FALSE()),0) -> 11129.148
A16: 11 | B16: =Amortissement!B22 -> 3914533.7 | C16: =Paramètres!B13+11 -> 51 | D16: =VLOOKUP(C16,Tables_CIMA!$A$5:$D$65,2,FALSE()) -> 889166 | E16: =VLOOKUP(C16,Tables_CIMA!$A$5:$D$65,3,FALSE()) -> 6704 | F16: =(1/(1+Paramètres!$B$8))^(11+0.5) -> 0.67326491 | G16: =IF(11<Paramètres!$B$6,B16*E16*F16/VLOOKUP(Paramètres!$B$13,Tables_CIMA!$A$5:$D$65,2,FALSE()),0) -> 18745.658 | H16: 11 | I16: =Amortissement!B22 -> 3914533.7 | J16: =Paramètres!C13+11 -> 49 | K16: =VLOOKUP(J16,Tables_CIMA!$E$5:$H$65,2,FALSE()) -> 945859 | L16: =VLOOKUP(J16,Tables_CIMA!$E$5:$H$65,3,FALSE()) -> 3472 | M16: =(1/(1+Paramètres!$B$8))^(11+0.5) -> 0.67326491 | N16: =IF(11<Paramètres!$B$6,I16*L16*M16/VLOOKUP(Paramètres!$C$13,Tables_CIMA!$E$5:$H$65,2,FALSE()),0) -> 9413.4461
A17: 12 | B17: =Amortissement!B23 -> 3049658.3 | C17: =Paramètres!B13+12 -> 52 | D17: =VLOOKUP(C17,Tables_CIMA!$A$5:$D$65,2,FALSE()) -> 882462 | E17: =VLOOKUP(C17,Tables_CIMA!$A$5:$D$65,3,FALSE()) -> 7027 | F17: =(1/(1+Paramètres!$B$8))^(12+0.5) -> 0.65049749 | G17: =IF(12<Paramètres!$B$6,B17*E17*F17/VLOOKUP(Paramètres!$B$13,Tables_CIMA!$A$5:$D$65,2,FALSE()),0) -> 14789.975 | H17: 12 | I17: =Amortissement!B23 -> 3049658.3 | J17: =Paramètres!C13+12 -> 50 | K17: =VLOOKUP(J17,Tables_CIMA!$E$5:$H$65,2,FALSE()) -> 942387 | L17: =VLOOKUP(J17,Tables_CIMA!$E$5:$H$65,3,FALSE()) -> 3647 | M17: =(1/(1+Paramètres!$B$8))^(12+0.5) -> 0.65049749 | N17: =IF(12<Paramètres!$B$6,I17*L17*M17/VLOOKUP(Paramètres!$C$13,Tables_CIMA!$E$5:$H$65,2,FALSE()),0) -> 7442.7852
A18: 13 | B18: =Amortissement!B24 -> 2112998.7 | C18: =Paramètres!B13+13 -> 53 | D18: =VLOOKUP(C18,Tables_CIMA!$A$5:$D$65,2,FALSE()) -> 875435 | E18: =VLOOKUP(C18,Tables_CIMA!$A$5:$D$65,3,FALSE()) -> 7359 | F18: =(1/(1+Paramètres!$B$8))^(13+0.5) -> 0.62849999 | G18: =IF(13<Paramètres!$B$6,B18*E18*F18/VLOOKUP(Paramètres!$B$13,Tables_CIMA!$A$5:$D$65,2,FALSE()),0) -> 10368.692 | H18: 13 | I18: =Amortissement!B24 -> 2112998.7 | J18: =Paramètres!C13+13 -> 51 | K18: =VLOOKUP(J18,Tables_CIMA!$E$5:$H$65,2,FALSE()) -> 938740 | L18: =VLOOKUP(J18,Tables_CIMA!$E$5:$H$65,3,FALSE()) -> 3837 | M18: =(1/(1+Paramètres!$B$8))^(13+0.5) -> 0.62849999 | N18: =IF(13<Paramètres!$B$6,I18*L18*M18/VLOOKUP(Paramètres!$C$13,Tables_CIMA!$E$5:$H$65,2,FALSE()),0) -> 5242.0265
A19: 14 | B19: =Amortissement!B25 -> 1098596.8 | C19: =Paramètres!B13+14 -> 54 | D19: =VLOOKUP(C19,Tables_CIMA!$A$5:$D$65,2,FALSE()) -> 868076 | E19: =VLOOKUP(C19,Tables_CIMA!$A$5:$D$65,3,FALSE()) -> 7711 | F19: =(1/(1+Paramètres!$B$8))^(14+0.5) -> 0.60724637 | G19: =IF(14<Paramètres!$B$6,B19*E19*F19/VLOOKUP(Paramètres!$B$13,Tables_CIMA!$A$5:$D$65,2,FALSE()),0) -> 5457.7624 | H19: 14 | I19: =Amortissement!B25 -> 1098596.8 | J19: =Paramètres!C13+14 -> 52 | K19: =VLOOKUP(J19,Tables_CIMA!$E$5:$H$65,2,FALSE()) -> 934903 | L19: =VLOOKUP(J19,Tables_CIMA!$E$5:$H$65,3,FALSE()) -> 4035 | M19: =(1/(1+Paramètres!$B$8))^(14+0.5) -> 0.60724637 | N19: =IF(14<Paramètres!$B$6,I19*L19*M19/VLOOKUP(Paramètres!$C$13,Tables_CIMA!$E$5:$H$65,2,FALSE()),0) -> 2769.1705
A21: TOTAUX | G21: =SUM(G5:G20) -> 395294.7 | N21: =SUM(N5:N20) -> 188010.08
A23: Prime pure unique (FCFA) | G23: =Paramètres!B14*G21 -> 276706.29 | H23: Prime pure unique (FCFA) | N23: =Paramètres!C14*N21 -> 56403.025
A24: Prime pure GLOBALE (FCFA) | G24: =G23+N23 -> 333109.32
A26: Rente-due | G26: =(VLOOKUP(Paramètres!B13,Commutation!$A$5:$E$65,5,FALSE())-VLOOKUP(Paramètres!B13+Paramètres!B6,Commutation!$A$5:$E$65,5,FALSE()))/VLOOKUP(Paramètres!B13,Commutation!$A$5:$E$65,2,FALSE()) -> 11.552483 | H26: Rente-due | N26: =(VLOOKUP(Paramètres!C13,Commutation!$F$5:$J$65,5,FALSE())-VLOOKUP(Paramètres!C13+Paramètres!B6,Commutation!$F$5:$J$65,5,FALSE()))/VLOOKUP(Paramètres!C13,Commutation!$F$5:$J$65,2,FALSE()) -> 11.746485
A27: Prime annuelle nette | G27: =G23/G26 -> 23952.107 | H27: Prime annuelle nette (FCFA/an) | N27: =N23/N26 -> 4801.6937
A28: Prime d'inventaire | G28: =(1+Paramètres!B17)*G27 -> 26347.317 | H28: Prime d'inventaire | N28: =(1+Paramètres!B17)*N27 -> 5281.863
A29: Prime commerciale | G29: =G28/(1-Paramètres!B18) -> 35129.756 | H29: Prime commerciale | N29: =N28/(1-Paramètres!B18) -> 7042.484
A30: Prime commerciale (FCFA/an) | G30: =G29+N29 -> 42172.24
A31: Prime mensuelle totale (FCFA/mois) | G31: =G30/12 -> 3514.3534
A32: TAEA = PC_total / C₀ (%) | G32: =G30/Paramètres!B5 -> 0.004217224

Sheet Provisions
A1: PROVISIONS MATHÉMATIQUES MÉTHODE PROSPECTIVE AVEC RÉCURRENCE DE FACKLER
A4: Année k | B4: PM1(k) FCFA | C4: PM1(k) FCFA | D4: PM Total FCFA | E4: PA1 (FCFA) | F4: Vérif Fackler 1 | G4: PA1 (FCFA) | H4: Vérif Fackler 2
A5: 0 | B5: =(Paramètres!$B$14/VLOOKUP(Paramètres!$B$13+0,Tables_CIMA!$A$5:$D$65,2,FALSE()))*SUMPRODUCT((Calcul_PP!$A$5:$A$19>=0)*(Calcul_PP!$A$5:$A$19<Paramètres!$B$6)*Calcul_PP!$B$5:$B$19*Calcul_PP!$E$5:$E$19*POWER(1/(1+Paramètres!$B$8),Calcul_PP!$A$5:$A$19-0+0.5))-Tarification!$B$23*(VLOOKUP(Paramètres!$B$13+0,Commutation!$A$5:$E$65,5,FALSE())-VLOOKUP(Paramètres!$B$13+Paramètres!$B$6,Commutation!$A$5:$E$65,5,FALSE()))/VLOOKUP(Paramètres!$B$13+0,Commutation!$A$5:$E$65,2,FALSE()) -> 0 | C5: =(Paramètres!$C$14/VLOOKUP(Paramètres!$C$13+0,Tables_CIMA!$E$5:$H$65,2,FALSE()))*SUMPRODUCT((Calcul_PP!$A$5:$A$19>=0)*(Calcul_PP!$A$5:$A$19<Paramètres!$B$6)*Calcul_PP!$B$5:$B$19*Calcul_PP!$L$5:$L$19*POWER(1/(1+Paramètres!$B$8),Calcul_PP!$A$5:$A$19-0+0.5))-Tarification!$C$23*(VLOOKUP(Paramètres!$C$13+0,Commutation!$F$5:$J$65,5,FALSE())-VLOOKUP(Paramètres!$C$13+Paramètres!$B$6,Commutation!$F$5:$J$65,5,FALSE()))/VLOOKUP(Paramètres!$C$13+0,Commutation!$F$5:$J$65,2,FALSE()) -> 0 | D5: =B5+C5 -> 0 | E5: =Tarification!B23 -> 23952.107 | F5: =(B5+Tarification!$B$23)*(1+Paramètres!$B$8)-Paramètres!$B$14*VLOOKUP(0,Calcul_PP!$A$5:$B$19,2,FALSE())*VLOOKUP(Paramètres!$B$13+0,Tables_CIMA!$A$5:$D$65,4,FALSE())*SQRT(1+Paramètres!$B$8)-(1-VLOOKUP(Paramètres!$B$13+0,Tables_CIMA!$A$5:$D$65,4,FALSE()))*B6 -> 6.7473138e-11 | G5: =Tarification!C23 -> 4801.6937 | H5: =(C5+Tarification!$C$23)*(1+Paramètres!$B$8)-Paramètres!$C$14*VLOOKUP(0,Calcul_PP!$A$5:$B$19,2,FALSE())*VLOOKUP(Paramètres!$C$13+0,Tables_CIMA!$E$5:$H$65,4,FALSE())*SQRT(1+Paramètres!$B$8)-(1-VLOOKUP(Paramètres!$C$13+0,Tables_CIMA!$E$5:$H$65,4,FALSE()))*C6 -> 3.9758419e-11
A6: 1 | B6: =(Paramètres!$B$14/VLOOKUP(Paramètres!$B$13+1,Tables_CIMA!$A$5:$D$65,2,FALSE()))*SUMPRODUCT((Calcul_PP!$A$5:$A$19>=1)*(Calcul_PP!$A$5:$A$19<Paramètres!$B$6)*Calcul_PP!$B$5:$B$19*Calcul_PP!$E$5:$E$19*POWER(1/(1+Paramètres!$B$8),Calcul_PP!$A$5:$A$19-1+0.5))-Tarification!$B$23*(VLOOKUP(Paramètres!$B$13+1,Commutation!$A$5:$E$65,5,FALSE())-VLOOKUP(Paramètres!$B$13+Paramètres!$B$6,Commutation!$A$5:$E$65,5,FALSE()))/VLOOKUP(Paramètres!$B$13+1,Commutation!$A$5:$E$65,2,FALSE()) -> -113.21904 | C6: =(Paramètres!$C$14/VLOOKUP(Paramètres!$C$13+1,Tables_CIMA!$E$5:$H$65,2,FALSE()))*SUMPRODUCT((Calcul_PP!$A$5:$A$19>=1)*(Calcul_PP!$A$5:$A$19<Paramètres!$B$6)*Calcul_PP!$B$5:$B$19*Calcul_PP!$L$5:$L$19*POWER(1/(1+Paramètres!$B$8),Calcul_PP!$A$5:$A$19-1+0.5))-Tarification!$C$23*(VLOOKUP(Paramètres!$C$13+1,Commutation!$F$5:$J$65,5,FALSE())-VLOOKUP(Paramètres!$C$13+Paramètres!$B$6,Commutation!$F$5:$J$65,5,FALSE()))/VLOOKUP(Paramètres!$C$13+1,Commutation!$F$5:$J$65,2,FALSE()) -> 18.405408 | D6: =B6+C6 -> -94.813635 | E6: =Tarification!B23 -> 23952.107 | F6: =(B6+Tarification!$B$23)*(1+Paramètres!$B$8)-Paramètres!$B$14*VLOOKUP(1,Calcul_PP!$A$5:$B$19,2,FALSE())*VLOOKUP(Paramètres!$B$13+1,Tables_CIMA!$A$5:$D$65,4,FALSE())*SQRT(1+Paramètres!$B$8)-(1-VLOOKUP(Paramètres!$B$13+1,Tables_CIMA!$A$5:$D$65,4,FALSE()))*B7 -> 8.0035534e-11 | G6: =Tarification!C23 -> 4801.6937 | H6: =(C6+Tarification!$C$23)*(1+Paramètres!$B$8)-Paramètres!$C$14*VLOOKUP(1,Calcul_PP!$A$5:$B$19,2,FALSE())*VLOOKUP(Paramètres!$C$13+1,Tables_CIMA!$E$5:$H$65,4,FALSE())*SQRT(1+Paramètres!$B$8)-(1-VLOOKUP(Paramètres!$C$13+1,Tables_CIMA!$E$5:$H$65,4,FALSE()))*C7 -> 1.3329782e-11
A7: 2 | B7: =(Paramètres!$B$14/VLOOKUP(Paramètres!$B$13+2,Tables_CIMA!$A$5:$D$65,2,FALSE()))*SUMPRODUCT((Calcul_PP!$A$5:$A$19>=2)*(Calcul_PP!$A$5:$A$19<Paramètres!$B$6)*Calcul_PP!$B$5:$B$19*Calcul_PP!$E$5:$E$19*POWER(1/(1+Paramètres!$B$8),Calcul_PP!$A$5:$A$19-2+0.5))-Tarification!$B$23*(VLOOKUP(Paramètres!$B$13+2,Commutation!$A$5:$E$65,5,FALSE())-VLOOKUP(Paramètres!$B$13+Paramètres!$B$6,Commutation!$A$5:$E$65,5,FALSE()))/VLOOKUP(Paramètres!$B$13+2,Commutation!$A$5:$E$65,2,FALSE()) -> -1529.1897 | C7: =(Paramètres!$C$14/VLOOKUP(Paramètres!$C$13+2,Tables_CIMA!$E$5:$H$65,2,FALSE()))*SUMPRODUCT((Calcul_PP!$A$5:$A$19>=2)*(Calcul_PP!$A$5:$A$19<Paramètres!$B$6)*Calcul_PP!$B$5:$B$19*Calcul_PP!$L$5:$L$19*POWER(1/(1+Paramètres!$B$8),Calcul_PP!$A$5:$A$19-2+0.5))-Tarification!$C$23*(VLOOKUP(Paramètres!$C$13+2,Commutation!$F$5:$J$65,5,FALSE())-VLOOKUP(Paramètres!$C$13+Paramètres!$B$6,Commutation!$F$5:$J$65,5,FALSE()))/VLOOKUP(Paramètres!$C$13+2,Commutation!$F$5:$J$65,2,FALSE()) -> -153.22819 | D7: =B7+C7 -> -1682.4179 | E7: =Tarification!B23 -> 23952.107 | F7: =(B7+Tarification!$B$23)*(1+Paramètres!$B$8)-Paramètres!$B$14*VLOOKUP(2,Calcul_PP!$A$5:$B$19,2,FALSE())*VLOOKUP(Paramètres!$B$13+2,Tables_CIMA!$A$5:$D$65,4,FALSE())*SQRT(1+Paramètres!$B$8)-(1-VLOOKUP(Paramètres!$B$13+2,Tables_CIMA!$A$5:$D$65,4,FALSE()))*B8 -> -6.3664629e-11 | G7: =Tarification!C23 -> 4801.6937 | H7: =(C7+Tarification!$C$23)*(1+Paramètres!$B$8)-Paramètres!$C$14*VLOOKUP(2,Calcul_PP!$A$5:$B$19,2,FALSE())*VLOOKUP(Paramètres!$C$13+2,Tables_CIMA!$E$5:$H$65,4,FALSE())*SQRT(1+Paramètres!$B$8)-(1-VLOOKUP(Paramètres!$C$13+2,Tables_CIMA!$E$5:$H$65,4,FALSE()))*C8 -> -1.0231815e-12
