Workbook

Sheet Simulateur
A1: SIMULATEUR ASSURANCE VIE MIXTE : EPARGNE ETUDES/CAPITAL AVEC GARANTIE DECES
A3: DONNEES DU CONTRAT | D3: RESULTATS DE LA SIMULATION
A4: Prime mensuelle (FCFA, minimum 5 000) | B4: 5000 | D4: Capital garanti (deces ou terme, FCFA) | E4: =Calculs!B12 -> 556441.26
A5: Duree du contrat n (annees, 5 a 10) | B5: 10 | D5: Prime pure unique PP (FCFA) | E5: =Calculs!B13 -> 395915.12
A6: Sexe de l’assure (H ou F) | B6: H | D6: Prime annuelle nette PA (FCFA/an) | E6: =Calculs!B14 -> 46363.636
A7: Age a la souscription (20 a 55 ans) | B7: 25 | D7: Prime d’inventaire PI (FCFA/an) | E7: =Calculs!B15 -> 51000
D8: Prime commerciale PC (FCFA/an) | E8: =Calculs!B16 -> 60000
A9: HYPOTHESES TECHNIQUES | D9: Total des primes versees sur n annees (FCFA) | E9: =Simulateur!$B$5*Calculs!B16 -> 600000
A10: Taux technique i | B10: 0.035 | D10: Rapport capital garanti / primes versees | E10: =E4/E9 -> 0.9274021
A11: Chargement d’inventaire delta | B11: 0.1
A12: Chargement commercial eta | B12: 0.15 | D12: EPARGNE ET RACHAT
A13: Penalite de rachat anticipe | B13: 0.05 | D13: Epargne acquise a mi-parcours (FCFA) | E13: =INDEX(Calculs!B36:B46,MATCH(ROUND(Simulateur!$B$5/2,0),Calculs!A36:A46,0)) -> 253143.34
A14: Quotite maximale d’avance | B14: 0.8 | D14: Valeur de rachat a mi-parcours (FCFA) | E14: =INDEX(Projection!E5:E15,MATCH(ROUND(Simulateur!$B$5/2,0),Projection!A5:A15,0)) -> 240486.17
A15: Delai de carence avant rachat (annees) | B15: 2 | D15: Capital exigible au terme (FCFA) | E15: =INDEX(Calculs!B36:B46,MATCH(Simulateur!$B$5,Calculs!A36:A46,0)) -> 556441.26

Sheet Projection
A1: PROJECTION ANNUELLE DU CONTRAT
A4: Annee k | B4: Age atteint | C4: Cumul des primes (FCFA) | D4: Epargne acquise PM(k) (FCFA) | E4: Valeur de rachat (FCFA) | F4: Avance maximale (FCFA)
A5: 0 | B5: =IF(A5>Simulateur!$B$5,"",Simulateur!$B$7+A5) -> 25 | C5: =IF(A5>Simulateur!$B$5,"",A5*Calculs!$B$16) -> 0 | D5: =Calculs!B36 -> -5.8207661e-11 | E5: =IF(D5="","",IF(A5<Simulateur!$B$15,0,IF(A5=Simulateur!$B$5,D5,D5*(1-Simulateur!$B$13)))) -> 0 | F5: =IF(E5="","",Simulateur!$B$14*E5) -> 0
A6: 1 | B6: =IF(A6>Simulateur!$B$5,"",Simulateur!$B$7+A6) -> 26 | C6: =IF(A6>Simulateur!$B$5,"",A6*Calculs!$B$16) -> 60000 | D6: =Calculs!B37 -> 47043.807 | E6: =IF(D6="","",IF(A6<Simulateur!$B$15,0,IF(A6=Simulateur!$B$5,D6,D6*(1-Simulateur!$B$13)))) -> 0 | F6: =IF(E6="","",Simulateur!$B$14*E6) -> 0
A7: 2 | B7: =IF(A7>Simulateur!$B$5,"",Simulateur!$B$7+A7) -> 27 | C7: =IF(A7>Simulateur!$B$5,"",A7*Calculs!$B$16) -> 120000 | D7: =Calculs!B38 -> 95805.681 | E7: =IF(D7="","",IF(A7<Simulateur!$B$15,0,IF(A7=Simulateur!$B$5,D7,D7*(1-Simulateur!$B$13)))) -> 91015.397 | F7: =IF(E7="","",Simulateur!$B$14*E7) -> 72812.318
A8: 3 | B8: =IF(A8>Simulateur!$B$5,"",Simulateur!$B$7+A8) -> 28 | C8: =IF(A8>Simulateur!$B$5,"",A8*Calculs!$B$16) -> 180000 | D8: =Calculs!B39 -> 146349.98 | E8: =IF(D8="","",IF(A8<Simulateur!$B$15,0,IF(A8=Simulateur!$B$5,D8,D8*(1-Simulateur!$B$13)))) -> 139032.48 | F8: =IF(E8="","",Simulateur!$B$14*E8) -> 111225.98
A9: 4 | B9: =IF(A9>Simulateur!$B$5,"",Simulateur!$B$7+A9) -> 29 | C9: =IF(A9>Simulateur!$B$5,"",A9*Calculs!$B$16) -> 240000 | D9: =Calculs!B40 -> 198743.47 | E9: =IF(D9="","",IF(A9<Simulateur!$B$15,0,IF(A9=Simulateur!$B$5,D9,D9*(1-Simulateur!$B$13)))) -> 188806.29 | F9: =IF(E9="","",Simulateur!$B$14*E9) -> 151045.03
A10: 5 | B10: =IF(A10>Simulateur!$B$5,"",Simulateur!$B$7+A10) -> 30 | C10: =IF(A10>Simulateur!$B$5,"",A10*Calculs!$B$16) -> 300000 | D10: =Calculs!B41 -> 253143.34 | E10: =IF(D10="","",IF(A10<Simulateur!$B$15,0,IF(A10=Simulateur!$B$5,D10,D10*(1-Simulateur!$B$13)))) -> 240486.17 | F10: =IF(E10="","",Simulateur!$B$14*E10) -> 192388.94
A11: 6 | B11: =IF(A11>Simulateur!$B$5,"",Simulateur!$B$7+A11) -> 31 | C11: =IF(A11>Simulateur!$B$5,"",A11*Calculs!$B$16) -> 360000 | D11: =Calculs!B42 -> 309477.96 | E11: =IF(D11="","",IF(A11<Simulateur!$B$15,0,IF(A11=Simulateur!$B$5,D11,D11*(1-Simulateur!$B$13)))) -> 294004.06 | F11: =IF(E11="","",Simulateur!$B$14*E11) -> 235203.25
A12: 7 | B12: =IF(A12>Simulateur!$B$5,"",Simulateur!$B$7+A12) -> 32 | C12: =IF(A12>Simulateur!$B$5,"",A12*Calculs!$B$16) -> 420000 | D12: =Calculs!B43 -> 367892.39 | E12: =IF(D12="","",IF(A12<Simulateur!$B$15,0,IF(A12=Simulateur!$B$5,D12,D12*(1-Simulateur!$B$13)))) -> 349497.77 | F12: =IF(E12="","",Simulateur!$B$14*E12) -> 279598.22
A13: 8 | B13: =IF(A13>Simulateur!$B$5,"",Simulateur!$B$7+A13) -> 33 | C13: =IF(A13>Simulateur!$B$5,"",A13*Calculs!$B$16) -> 480000 | D13: =Calculs!B44 -> 428464.97 | E13: =IF(D13="","",IF(A13<Simulateur!$B$15,0,IF(A13=Simulateur!$B$5,D13,D13*(1-Simulateur!$B$13)))) -> 407041.72 | F13: =IF(E13="","",Simulateur!$B$14*E13) -> 325633.38
A14: 9 | B14: =IF(A14>Simulateur!$B$5,"",Simulateur!$B$7+A14) -> 34 | C14: =IF(A14>Simulateur!$B$5,"",A14*Calculs!$B$16) -> 540000 | D14: =Calculs!B45 -> 491282.61 | E14: =IF(D14="","",IF(A14<Simulateur!$B$15,0,IF(A14=Simulateur!$B$5,D14,D14*(1-Simulateur!$B$13)))) -> 466718.48 | F14: =IF(E14="","",Simulateur!$B$14*E14) -> 373374.78
A15: 10 | B15: =IF(A15>Simulateur!$B$5,"",Simulateur!$B$7+A15) -> 35 | C15: =IF(A15>Simulateur!$B$5,"",A15*Calculs!$B$16) -> 600000 | D15: =Calculs!B46 -> 556441.26 | E15: =IF(D15="","",IF(A15<Simulateur!$B$15,0,IF(A15=Simulateur!$B$5,D15,D15*(1-Simulateur!$B$13)))) -> 556441.26 | F15: =IF(E15="","",Simulateur!$B$14*E15) -> 445153.01

Sheet Calculs
A1: MOTEUR ACTUARIEL : VALEURS UNITAIRES, TARIFICATION, PROVISIONS ET CONTROLES
A3: 1. VALEURS ACTUARIELLES PAR UNITE DE CAPITAL GARANTI
A4: A_deces | B4: =(VLOOKUP(Simulateur!$B$7,Commutation!$A$4:$H$64,7,FALSE())-VLOOKUP(Simulateur!$B$7+Simulateur!$B$5,Commutation!$A$4:$H$64,7,FALSE()))/VLOOKUP(Simulateur!$B$7,Commutation!$A$4:$H$64,5,FALSE()) -> 0.016595623
A5: A_survie | B5: =VLOOKUP(Simulateur!$B$7+Simulateur!$B$5,Commutation!$A$4:$H$64,5,FALSE())/VLOOKUP(Simulateur!$B$7,Commutation!$A$4:$H$64,5,FALSE()) -> 0.69491725
A6: A_mixte | B6: =B4+B5 -> 0.71151287
A7: Rente-due temporaire a(x:n) | B7: =(VLOOKUP(Simulateur!$B$7,Commutation!$A$4:$H$64,8,FALSE())-VLOOKUP(Simulateur!$B$7+Simulateur!$B$5,Commutation!$A$4:$H$64,8,FALSE()))/VLOOKUP(Simulateur!$B$7,Commutation!$A$4:$H$64,5,FALSE()) -> 8.5393457
A8: Prime annuelle nette par unite PA_unit | B8: =B6/B7 -> 0.083321708
A9: Prime commerciale annuelle par unite PC_unit | B9: =(1+Simulateur!$B$11)*B8/(1-Simulateur!$B$12) -> 0.10782809
A11: 2. TARIFICATION EN FCFA
A12: Capital garanti C | B12: =12*Simulateur!$B$4/B9 -> 556441.26
A13: Prime pure unique PP | B13: =B12*B6 -> 395915.12
A14: Prime annuelle nette PA | B14: =B12*B8 -> 46363.636
A15: Prime d’inventaire PI | B15: =(1+Simulateur!$B$11)*B14 -> 51000
A16: Prime commerciale PC | B16: =B15/(1-Simulateur!$B$12) -> 60000
A17: Prime mensuelle recalculee (controle) | B17: =B16/12 -> 5000
A19: 3. COMPOSANTE DECES ANNEE PAR ANNEE (VERIFICATION)
A20: k | B20: Age x+k | C20: l_(x+k) | D20: d_(x+k) | E20: v^(k+0,5) | F20: phi_k
A21: 0 | B21: =Simulateur!$B$7+A21 -> 25 | C21: =VLOOKUP(B21,Commutation!$A$4:$H$64,2,FALSE()) -> 975262 | D21: =VLOOKUP(B21,Commutation!$A$4:$H$64,3,FALSE()) -> 1771 | E21: =POWER(1/(1+Simulateur!$B$10),A21+0.5) -> 0.98294637 | F21: =IF(A21<Simulateur!$B$5,D21*E21/VLOOKUP(Simulateur!$B$7,Commutation!$A$4:$H$64,2,FALSE()),0) -> 0.0017849542
A22: 1 | B22: =Simulateur!$B$7+A22 -> 26 | C22: =VLOOKUP(B22,Commutation!$A$4:$H$64,2,FALSE()) -> 973491 | D22: =VLOOKUP(B22,Commutation!$A$4:$H$64,3,FALSE()) -> 1803 | E22: =POWER(1/(1+Simulateur!$B$10),A22+0.5) -> 0.94970664 | F22: =IF(A22<Simulateur!$B$5,D22*E22/VLOOKUP(Simulateur!$B$7,Commutation!$A$4:$H$64,2,FALSE()),0) -> 0.0017557549
A23: 2 | B23: =Simulateur!$B$7+A23 -> 27 | C23: =VLOOKUP(B23,Commutation!$A$4:$H$64,2,FALSE()) -> 971688 | D23: =VLOOKUP(B23,Commutation!$A$4:$H$64,3,FALSE()) -> 1841 | E23: =POWER(1/(1+Simulateur!$B$10),A23+0.5) -> 0.91759096 | F23: =IF(A23<Simulateur!$B$5,D23*E23/VLOOKUP(Simulateur!$B$7,Commutation!$A$4:$H$64,2,FALSE()),0) -> 0.0017321345
A24: 3 | B24: =Simulateur!$B$7+A24 -> 28 | C24: =VLOOKUP(B24,Commutation!$A$4:$H$64,2,FALSE()) -> 969847 | D24: =VLOOKUP(B24,Commutation!$A$4:$H$64,3,FALSE()) -> 1888 | E24: =POWER(1/(1+Simulateur!$B$10),A24+0.5) -> 0.88656131 | F24: =IF(A24<Simulateur!$B$5,D24*E24/VLOOKUP(Simulateur!$B$7,Commutation!$A$4:$H$64,2,FALSE()),0) -> 0.0017162852
A25: 4 | B25: =Simulateur!$B$7+A25 -> 29 | C25: =VLOOKUP(B25,Commutation!$A$4:$H$64,2,FALSE()) -> 967959 | D25: =VLOOKUP(B25,Commutation!$A$4:$H$64,3,FALSE()) -> 1678 | E25: =POWER(1/(1+Simulateur!$B$10),A25+0.5) -> 0.85658098 | F25: =IF(A25<Simulateur!$B$5,D25*E25/VLOOKUP(Simulateur!$B$7,Commutation!$A$4:$H$64,2,FALSE()),0) -> 0.0014738018
A26: 5 | B26: =Simulateur!$B$7+A26 -> 30 | C26: =VLOOKUP(B26,Commutation!$A$4:$H$64,2,FALSE()) -> 966281 | D26: =VLOOKUP(B26,Commutation!$A$4:$H$64,3,FALSE()) -> 1927 | E26: =POWER(1/(1+Simulateur!$B$10),A26+0.5) -> 0.82761447 | F26: =IF(A26<Simulateur!$B$5,D26*E26/VLOOKUP(Simulateur!$B$7,Commutation!$A$4:$H$64,2,FALSE()),0) -> 0.0016352663
A27: 6 | B27: =Simulateur!$B$7+A27 -> 31 | C27: =VLOOKUP(B27,Commutation!$A$4:$H$64,2,FALSE()) -> 964354 | D27: =VLOOKUP(B27,Commutation!$A$4:$H$64,3,FALSE()) -> 1964 | E27: =POWER(1/(1+Simulateur!$B$10),A27+0.5) -> 0.79962751 | F27: =IF(A27<Simulateur!$B$5,D27*E27/VLOOKUP(Simulateur!$B$7,Commutation!$A$4:$H$64,2,FALSE()),0) -> 0.0016103041
A28: 7 | B28: =Simulateur!$B$7+A28 -> 32 | C28: =VLOOKUP(B28,Commutation!$A$4:$H$64,2,FALSE()) -> 962390 | D28: =VLOOKUP(B28,Commutation!$A$4:$H$64,3,FALSE()) -> 2028 | E28: =POWER(1/(1+Simulateur!$B$10),A28+0.5) -> 0.77258697 | F28: =IF(A28<Simulateur!$B$5,D28*E28/VLOOKUP(Simulateur!$B$7,Commutation!$A$4:$H$64,2,FALSE()),0) -> 0.0016065492
A29: 8 | B29: =Simulateur!$B$7+A29 -> 33 | C29: =VLOOKUP(B29,Commutation!$A$4:$H$64,2,FALSE()) -> 960362 | D29: =VLOOKUP(B29,Commutation!$A$4:$H$64,3,FALSE()) -> 2118 | E29: =POWER(1/(1+Simulateur!$B$10),A29+0.5) -> 0.74646084 | F29: =IF(A29<Simulateur!$B$5,D29*E29/VLOOKUP(Simulateur!$B$7,Commutation!$A$4:$H$64,2,FALSE()),0) -> 0.001621107
A30: 9 | B30: =Simulateur!$B$7+A30 -> 34 | C30: =VLOOKUP(B30,Commutation!$A$4:$H$64,2,FALSE()) -> 958244 | D30: =VLOOKUP(B30,Commutation!$A$4:$H$64,3,FALSE()) -> 2244 | E30: =POWER(1/(1+Simulateur!$B$10),A30+0.5) -> 0.7212182 | F30: =IF(A30<Simulateur!$B$5,D30*E30/VLOOKUP(Simulateur!$B$7,Commutation!$A$4:$H$64,2,FALSE()),0) -> 0.0016594655
A31: A_deces directe | F31: =SUM(F21:F30) -> 0.016595623
A32: Ecart contre la valeur par commutation (doit etre proche de zero) | F32: =F31-B4 -> 0
A34: 4. PROVISIONS MATHEMATIQUES ET RECURRENCE DE FACKLER
A35: Annee k | B35: PM(k) (FCFA) | C35: q_(x+k) | D35: Verification Fackler (FCFA) | E35: Ecart absolu
A36: 0 | B36: =IF(A36>Simulateur!$B$5,"",IF(A36=Simulateur!$B$5,$B$12,$B$12*((VLOOKUP(Simulateur!$B$7+A36,Commutation!$A$4:$H$64,7,FALSE())-VLOOKUP(Simulateur!$B$7+Simulateur!$B$5,Commutation!$A$4:$H$64,7,FALSE())+VLOOKUP(Simulateur!$B$7+Simulateur!$B$5,Commutation!$A$4:$H$64,5,FALSE()))/VLOOKUP(Simulateur!$B$7+A36,Commutation!$A$4:$H$64,5,FALSE()))-$B$14*(VLOOKUP(Simulateur!$B$7+A36,Commutation!$A$4:$H$64,8,FALSE())-VLOOKUP(Simulateur!$B$7+Simulateur!$B$5,Commutation!$A$4:$H$64,8,FALSE()))/VLOOKUP(Simulateur!$B$7+A36,Commutation!$A$4:$H$64,5,FALSE()))) -> -5.8207661e-11 | C36: =IF(A36>=Simulateur!$B$5,"",VLOOKUP(Simulateur!$B$7+A36,Commutation!$A$4:$H$64,4,FALSE())) -> 0.0018159223 | D36: =IF(A36>=Simulateur!$B$5,"",(B36+$B$14)*(1+Simulateur!$B$10)-$B$12*C36*POWER(1+Simulateur!$B$10,0.5)-(1-C36)*B37) -> 6.5483619e-11 | E36: =IF(D36="",0,ABS(D36)) -> 6.5483619e-11
A37: 1 | B37: =IF(A37>Simulateur!$B$5,"",IF(A37=Simulateur!$B$5,$B$12,$B$12*((VLOOKUP(Simulateur!$B$7+A37,Commutation!$A$4:$H$64,7,FALSE())-VLOOKUP(Simulateur!$B$7+Simulateur!$B$5,Commutation!$A$4:$H$64,7,FALSE())+VLOOKUP(Simulateur!$B$7+Simulateur!$B$5,Commutation!$A$4:$H$64,5,FALSE()))/VLOOKUP(Simulateur!$B$7+A37,Commutation!$A$4:$H$64,5,FALSE()))-$B$14*(VLOOKUP(Simulateur!$B$7+A37,Commutation!$A$4:$H$64,8,FALSE())-VLOOKUP(Simulateur!$B$7+Simulateur!$B$5,Commutation!$A$4:$H$64,8,FALSE()))/VLOOKUP(Simulateur!$B$7+A37,Commutation!$A$4:$H$64,5,FALSE()))) -> 47043.807 | C37: =IF(A37>=Simulateur!$B$5,"",VLOOKUP(Simulateur!$B$7+A37,Commutation!$A$4:$H$64,4,FALSE())) -> 0.0018520972 | D37: =IF(A37>=Simulateur!$B$5,"",(B37+$B$14)*(1+Simulateur!$B$10)-$B$12*C37*POWER(1+Simulateur!$B$10,0.5)-(1-C37)*B38) -> -3.783498e-10 | E37: =IF(D37="",0,ABS(D37)) -> 3.783498e-10
A38: 2 | B38: =IF(A38>Simulateur!$B$5,"",IF(A38=Simulateur!$B$5,$B$12,$B$12*((VLOOKUP(Simulateur!$B$7+A38,Commutation!$A$4:$H$64,7,FALSE())-VLOOKUP(Simulateur!$B$7+Simulateur!$B$5,Commutation!$A$4:$H$64,7,FALSE())+VLOOKUP(Simulateur!$B$7+Simulateur!$B$5,Commutation!$A$4:$H$64,5,FALSE()))/VLOOKUP(Simulateur!$B$7+A38,Commutation!$A$4:$H$64,5,FALSE()))-$B$14*(VLOOKUP(Simulateur!$B$7+A38,Commutation!$A$4:$H$64,8,FALSE())-VLOOKUP(Simulateur!$B$7+Simulateur!$B$5,Commutation!$A$4:$H$64,8,FALSE()))/VLOOKUP(Simulateur!$B$7+A38,Commutation!$A$4:$H$64,5,FALSE()))) -> 95805.681 | C38: =IF(A38>=Simulateur!$B$5,"",VLOOKUP(Simulateur!$B$7+A38,Commutation!$A$4:$H$64,4,FALSE())) -> 0.0018946411 | D38: =IF(A38>=Simulateur!$B$5,"",(B38+$B$14)*(1+Simulateur!$B$10)-$B$12*C38*POWER(1+Simulateur!$B$10,0.5)-(1-C38)*B39) -> -1.1641532e-10 | E38: =IF(D38="",0,ABS(D38)) -> 1.1641532e-10
A39: 3 | B39: =IF(A39>Simulateur!$B$5,"",IF(A39=Simulateur!$B$5,$B$12,$B$12*((VLOOKUP(Simulateur!$B$7+A39,Commutation!$A$4:$H$64,7,FALSE())-VLOOKUP(Simulateur!$B$7+Simulateur!$B$5,Commutation!$A$4:$H$64,7,FALSE())+VLOOKUP(Simulateur!$B$7+Simulateur!$B$5,Commutation!$A$4:$H$64,5,FALSE()))/VLOOKUP(Simulateur!$B$7+A39,Commutation!$A$4:$H$64,5,FALSE()))-$B$14*(VLOOKUP(Simulateur!$B$7+A39,Commutation!$A$4:$H$64,8,FALSE())-VLOOKUP(Simulateur!$B$7+Simulateur!$B$5,Commutation!$A$4:$H$64,8,FALSE()))/VLOOKUP(Simulateur!$B$7+A39,Commutation!$A$4:$H$64,5,FALSE()))) -> 146349.98 | C39: =IF(A39>=Simulateur!$B$5,"",VLOOKUP(Simulateur!$B$7+A39,Commutation!$A$4:$H$64,4,FALSE())) -> 0.0019466988 | D39: =IF(A39>=Simulateur!$B$5,"",(B39+$B$14)*(1+Simulateur!$B$10)-$B$12*C39*POWER(1+Simulateur!$B$10,0.5)-(1-C39)*B40) -> -5.8207661e-11 | E39: =IF(D39="",0,ABS(D39)) -> 5.8207661e-11
A40: 4 | B40: =IF(A40>Simulateur!$B$5,"",IF(A40=Simulateur!$B$5,$B$12,$B$12*((VLOOKUP(Simulateur!$B$7+A40,Commutation!$A$4:$H$64,7,FALSE())-VLOOKUP(Simulateur!$B$7+Simulateur!$B$5,Commutation!$A$4:$H$64,7,FALSE())+VLOOKUP(Simulateur!$B$7+Simulateur!$B$5,Commutation!$A$4:$H$64,5,FALSE()))/VLOOKUP(Simulateur!$B$7+A40,Commutation!$A$4:$H$64,5,FALSE()))-$B$14*(VLOOKUP(Simulateur!$B$7+A40,Commutation!$A$4:$H$64,8,FALSE())-VLOOKUP(Simulateur!$B$7+Simulateur!$B$5,Commutation!$A$4:$H$64,8,FALSE()))/VLOOKUP(Simulateur!$B$7+A40,Commutation!$A$4:$H$64,5,FALSE()))) -> 198743.47 | C40: =IF(A40>=Simulateur!$B$5,"",VLOOKUP(Simulateur!$B$7+A40,Commutation!$A$4:$H$64,4,FALSE())) -> 0.0017335445 | D40: =IF(A40>=Simulateur!$B$5,"",(B40+$B$14)*(1+Simulateur!$B$10)-$B$12*C40*POWER(1+Simulateur!$B$10,0.5)-(1-C40)*B41) -> -2.910383e-11 | E40: =IF(D40="",0,ABS(D40)) -> 2.910383e-11
A41: 5 | B41: =IF(A41>Simulateur!$B$5,"",IF(A41=Simulateur!$B$5,$B$12,$B$12*((VLOOKUP(Simulateur!$B$7+A41,Commutation!$A$4:$H$64,7,FALSE())-VLOOKUP(Simulateur!$B$7+Simulateur!$B$5,Commutation!$A$4:$H$64,7,FALSE())+VLOOKUP(Simulateur!$B$7+Simulateur!$B$5,Commutation!$A$4:$H$64,5,FALSE()))/VLOOKUP(Simulateur!$B$7+A41,Commutation!$A$4:$H$64,5,FALSE()))-$B$14*(VLOOKUP(Simulateur!$B$7+A41,Commutation!$A$4:$H$64,8,FALSE())-VLOOKUP(Simulateur!$B$7+Simulateur!$B$5,Commutation!$A$4:$H$64,8,FALSE()))/VLOOKUP(Simulateur!$B$7+A41,Commutation!$A$4:$H$64,5,FALSE()))) -> 253143.34 | C41: =IF(A41>=Simulateur!$B$5,"",VLOOKUP(Simulateur!$B$7+A41,Commutation!$A$4:$H$64,4,FALSE())) -> 0.0019942439 | D41: =IF(A41>=Simulateur!$B$5,"",(B41+$B$14)*(1+Simulateur!$B$10)-$B$12*C41*POWER(1+Simulateur!$B$10,0.5)-(1-C41)*B42) -> 0 | E41: =IF(D41="",0,ABS(D41)) -> 0
A42: 6 | B42: =IF(A42>Simulateur!$B$5,"",IF(A42=Simulateur!$B$5,$B$12,$B$12*((VLOOKUP(Simulateur!$B$7+A42,Commutation!$A$4:$H$64,7,FALSE())-VLOOKUP(Simulateur!$B$7+Simulateur!$B$5,Commutation!$A$4:$H$64,7,FALSE())+VLOOKUP(Simulateur!$B$7+Simulateur!$B$5,Commutation!$A$4:$H$64,5,FALSE()))/VLOOKUP(Simulateur!$B$7+A42,Commutation!$A$4:$H$64,5,FALSE()))-$B$14*(VLOOKUP(Simulateur!$B$7+A42,Commutation!$A$4:$H$64,8,FALSE())-VLOOKUP(Simulateur!$B$7+Simulateur!$B$5,Commutation!$A$4:$H$64,8,FALSE()))/VLOOKUP(Simulateur!$B$7+A42,Commutation!$A$4:$H$64,5,FALSE()))) -> 309477.96 | C42: =IF(A42>=Simulateur!$B$5,"",VLOOKUP(Simulateur!$B$7+A42,Commutation!$A$4:$H$64,4,FALSE())) -> 0.0020365965 | D42: =IF(A42>=Simulateur!$B$5,"",(B42+$B$14)*(1+Simulateur!$B$10)-$B$12*C42*POWER(1+Simulateur!$B$10,0.5)-(1-C42)*B43) -> 1.7462298e-10 | E42: =IF(D42="",0,ABS(D42)) -> 1.7462298e-10
A43: 7 | B43: =IF(A43>Simulateur!$B$5,"",IF(A43=Simulateur!$B$5,$B$12,$B$12*((VLOOKUP(Simulateur!$B$7+A43,Commutation!$A$4:$H$64,7,FALSE())-VLOOKUP(Simulateur!$B$7+Simulateur!$B$5,Commutation!$A$4:$H$64,7,FALSE())+VLOOKUP(Simulateur!$B$7+Simulateur!$B$5,Commutation!$A$4:$H$64,5,FALSE()))/VLOOKUP(Simulateur!$B$7+A43,Commutation!$A$4:$H$64,5,FALSE()))-$B$14*(VLOOKUP(Simulateur!$B$7+A43,Commutation!$A$4:$H$64,8,FALSE())-VLOOKUP(Simulateur!$B$7+Simulateur!$B$5,Commutation!$A$4:$H$64,8,FALSE()))/VLOOKUP(Simulateur!$B$7+A43,Commutation!$A$4:$H$64,5,FALSE()))) -> 367892.39 | C43: =IF(A43>=Simulateur!$B$5,"",VLOOKUP(Simulateur!$B$7+A43,Commutation!$A$4:$H$64,4,FALSE())) -> 0.0021072538 | D43: =IF(A43>=Simulateur!$B$5,"",(B43+$B$14)*(1+Simulateur!$B$10)-$B$12*C43*POWER(1+Simulateur!$B$10,0.5)-(1-C43)*B44) -> -3.4924597e-10 | E43: =IF(D43="",0,ABS(D43)) -> 3.4924597e-10
A44: 8 | B44: =IF(A44>Simulateur!$B$5,"",IF(A44=Simulateur!$B$5,$B$12,$B$12*((VLOOKUP(Simulateur!$B$7+A44,Commutation!$A$4:$H$64,7,FALSE())-VLOOKUP(Simulateur!$B$7+Simulateur!$B$5,Commutation!$A$4:$H$64,7,FALSE())+VLOOKUP(Simulateur!$B$7+Simulateur!$B$5,Commutation!$A$4:$H$64,5,FALSE()))/VLOOKUP(Simulateur!$B$7+A44,Commutation!$A$4:$H$64,5,FALSE()))-$B$14*(VLOOKUP(Simulateur!$B$7+A44,Commutation!$A$4:$H$64,8,FALSE())-VLOOKUP(Simulateur!$B$7+Simulateur!$B$5,Commutation!$A$4:$H$64,8,FALSE()))/VLOOKUP(Simulateur!$B$7+A44,Commutation!$A$4:$H$64,5,FALSE()))) -> 428464.97 | C44: =IF(A44>=Simulateur!$B$5,"",VLOOKUP(Simulateur!$B$7+A44,Commutation!$A$4:$H$64,4,FALSE())) -> 0.0022054184 | D44: =IF(A44>=Simulateur!$B$5,"",(B44+$B$14)*(1+Simulateur!$B$10)-$B$12*C44*POWER(1+Simulateur!$B$10,0.5)-(1-C44)*B45) -> -2.910383e-10 | E44: =IF(D44="",0,ABS(D44)) -> 2.910383e-10
...

Sheet Commutation
A1: TABLE ACTIVE ET FONCTIONS DE COMMUTATION
A3: Age x | B3: l_x | C3: d_x | D3: q_x | E3: D_x | F3: C_x | G3: M_x | H3: N_x
A4: =Tables_CIMA!A4 -> 20 | B4: =IF(Simulateur!$B$6="H",Tables_CIMA!B4,Tables_CIMA!F4) -> 983382 | C4: =IF(Simulateur!$B$6="H",Tables_CIMA!C4,Tables_CIMA!G4) -> 1549 | D4: =IF(Simulateur!$B$6="H",Tables_CIMA!D4,Tables_CIMA!H4) -> 0.0015751763 | E4: =B4*POWER(1/(1+Simulateur!$B$10),A4) -> 494214.24 | F4: =C4*POWER(1/(1+Simulateur!$B$10),A4+0.5) -> 765.19874 | G4: =SUM(F4:F$64) -> 97421.339 | H4: =SUM(E4:E$64) -> 11782863
A5: =Tables_CIMA!A5 -> 21 | B5: =IF(Simulateur!$B$6="H",Tables_CIMA!B5,Tables_CIMA!F5) -> 981833 | C5: =IF(Simulateur!$B$6="H",Tables_CIMA!C5,Tables_CIMA!G5) -> 1612 | D5: =IF(Simulateur!$B$6="H",Tables_CIMA!D5,Tables_CIMA!H5) -> 0.0016418271 | E5: =B5*POWER(1/(1+Simulateur!$B$10),A5) -> 476749.54 | F5: =C5*POWER(1/(1+Simulateur!$B$10),A5+0.5) -> 769.39174 | G5: =SUM(F5:F$64) -> 96656.141 | H5: =SUM(E5:E$64) -> 11288648
A6: =Tables_CIMA!A6 -> 22 | B6: =IF(Simulateur!$B$6="H",Tables_CIMA!B6,Tables_CIMA!F6) -> 980221 | C6: =IF(Simulateur!$B$6="H",Tables_CIMA!C6,Tables_CIMA!G6) -> 1665 | D6: =IF(Simulateur!$B$6="H",Tables_CIMA!D6,Tables_CIMA!H6) -> 0.0016985965 | E6: =B6*POWER(1/(1+Simulateur!$B$10),A6) -> 459871.3 | F6: =C6*POWER(1/(1+Simulateur!$B$10),A6+0.5) -> 767.8146 | G6: =SUM(F6:F$64) -> 95886.749 | H6: =SUM(E6:E$64) -> 10811899
A7: =Tables_CIMA!A7 -> 23 | B7: =IF(Simulateur!$B$6="H",Tables_CIMA!B7,Tables_CIMA!F7) -> 978556 | C7: =IF(Simulateur!$B$6="H",Tables_CIMA!C7,Tables_CIMA!G7) -> 1720 | D7: =IF(Simulateur!$B$6="H",Tables_CIMA!D7,Tables_CIMA!H7) -> 0.0017576919 | E7: =B7*POWER(1/(1+Simulateur!$B$10),A7) -> 443565.38 | F7: =C7*POWER(1/(1+Simulateur!$B$10),A7+0.5) -> 766.35541 | G7: =SUM(F7:F$64) -> 95118.934 | H7: =SUM(E7:E$64) -> 10352028
A8: =Tables_CIMA!A8 -> 24 | B8: =IF(Simulateur!$B$6="H",Tables_CIMA!B8,Tables_CIMA!F8) -> 976836 | C8: =IF(Simulateur!$B$6="H",Tables_CIMA!C8,Tables_CIMA!G8) -> 1574 | D8: =IF(Simulateur!$B$6="H",Tables_CIMA!D8,Tables_CIMA!H8) -> 0.0016113247 | E8: =B8*POWER(1/(1+Simulateur!$B$10),A8) -> 427812.29 | F8: =C8*POWER(1/(1+Simulateur!$B$10),A8+0.5) -> 677.58871 | G8: =SUM(F8:F$64) -> 94352.579 | H8: =SUM(E8:E$64) -> 9908462.2
A9: =Tables_CIMA!A9 -> 25 | B9: =IF(Simulateur!$B$6="H",Tables_CIMA!B9,Tables_CIMA!F9) -> 975262 | C9: =IF(Simulateur!$B$6="H",Tables_CIMA!C9,Tables_CIMA!G9) -> 1771 | D9: =IF(Simulateur!$B$6="H",Tables_CIMA!D9,Tables_CIMA!H9) -> 0.0018159223 | E9: =B9*POWER(1/(1+Simulateur!$B$10),A9) -> 412679.18 | F9: =C9*POWER(1/(1+Simulateur!$B$10),A9+0.5) -> 736.61344 | G9: =SUM(F9:F$64) -> 93674.99 | H9: =SUM(E9:E$64) -> 9480649.9
A10: =Tables_CIMA!A10 -> 26 | B10: =IF(Simulateur!$B$6="H",Tables_CIMA!B10,Tables_CIMA!F10) -> 973491 | C10: =IF(Simulateur!$B$6="H",Tables_CIMA!C10,Tables_CIMA!G10) -> 1803 | D10: =IF(Simulateur!$B$6="H",Tables_CIMA!D10,Tables_CIMA!H10) -> 0.0018520972 | E10: =B10*POWER(1/(1+Simulateur!$B$10),A10) -> 397999.79 | F10: =C10*POWER(1/(1+Simulateur!$B$10),A10+0.5) -> 724.56351 | G10: =SUM(F10:F$64) -> 92938.377 | H10: =SUM(E10:E$64) -> 9067970.7
A11: =Tables_CIMA!A11 -> 27 | B11: =IF(Simulateur!$B$6="H",Tables_CIMA!B11,Tables_CIMA!F11) -> 971688 | C11: =IF(Simulateur!$B$6="H",Tables_CIMA!C11,Tables_CIMA!G11) -> 1841 | D11: =IF(Simulateur!$B$6="H",Tables_CIMA!D11,Tables_CIMA!H11) -> 0.0018946411 | E11: =B11*POWER(1/(1+Simulateur!$B$10),A11) -> 383828.66 | F11: =C11*POWER(1/(1+Simulateur!$B$10),A11+0.5) -> 714.81584 | G11: =SUM(F11:F$64) -> 92213.813 | H11: =SUM(E11:E$64) -> 8669970.9
A12: =Tables_CIMA!A12 -> 28 | B12: =IF(Simulateur!$B$6="H",Tables_CIMA!B12,Tables_CIMA!F12) -> 969847 | C12: =IF(Simulateur!$B$6="H",Tables_CIMA!C12,Tables_CIMA!G12) -> 1888 | D12: =IF(Simulateur!$B$6="H",Tables_CIMA!D12,Tables_CIMA!H12) -> 0.0019466988 | E12: =B12*POWER(1/(1+Simulateur!$B$10),A12) -> 370146.32 | F12: =C12*POWER(1/(1+Simulateur!$B$10),A12+0.5) -> 708.27518 | G12: =SUM(F12:F$64) -> 91498.997 | H12: =SUM(E12:E$64) -> 8286142.3
A13: =Tables_CIMA!A13 -> 29 | B13: =IF(Simulateur!$B$6="H",Tables_CIMA!B13,Tables_CIMA!F13) -> 967959 | C13: =IF(Simulateur!$B$6="H",Tables_CIMA!C13,Tables_CIMA!G13) -> 1678 | D13: =IF(Simulateur!$B$6="H",Tables_CIMA!D13,Tables_CIMA!H13) -> 0.0017335445 | E13: =B13*POWER(1/(1+Simulateur!$B$10),A13) -> 356933.1 | F13: =C13*POWER(1/(1+Simulateur!$B$10),A13+0.5) -> 608.20731 | G13: =SUM(F13:F$64) -> 90790.722 | H13: =SUM(E13:E$64) -> 7915995.9
A14: =Tables_CIMA!A14 -> 30 | B14: =IF(Simulateur!$B$6="H",Tables_CIMA!B14,Tables_CIMA!F14) -> 966281 | C14: =IF(Simulateur!$B$6="H",Tables_CIMA!C14,Tables_CIMA!G14) -> 1927 | D14: =IF(Simulateur!$B$6="H",Tables_CIMA!D14,Tables_CIMA!H14) -> 0.0019942439 | E14: =B14*POWER(1/(1+Simulateur!$B$10),A14) -> 344265.06 | F14: =C14*POWER(1/(1+Simulateur!$B$10),A14+0.5) -> 674.84036 | G14: =SUM(F14:F$64) -> 90182.515 | H14: =SUM(E14:E$64) -> 7559062.8
A15: =Tables_CIMA!A15 -> 31 | B15: =IF(Simulateur!$B$6="H",Tables_CIMA!B15,Tables_CIMA!F15) -> 964354 | C15: =IF(Simulateur!$B$6="H",Tables_CIMA!C15,Tables_CIMA!G15) -> 1964 | D15: =IF(Simulateur!$B$6="H",Tables_CIMA!D15,Tables_CIMA!H15) -> 0.0020365965 | E15: =B15*POWER(1/(1+Simulateur!$B$10),A15) -> 331959.91 | F15: =C15*POWER(1/(1+Simulateur!$B$10),A15+0.5) -> 664.53899 | G15: =SUM(F15:F$64) -> 89507.675 | H15: =SUM(E15:E$64) -> 7214797.8
... A64: =Tables_CIMA!A64 -> 80 | B64: =IF(Simulateur!$B$6="H",Tables_CIMA!B64,Tables_CIMA!F64) -> 384899 | C64: =IF(Simulateur!$B$6="H",Tables_CIMA!C64,Tables_CIMA!G64) -> 384899 | D64: =IF(Simulateur!$B$6="H",Tables_CIMA!D64,Tables_CIMA!H64) -> 1 | E64: =B64*POWER(1/(1+Simulateur!$B$10),A64) -> 24553.805 | F64: =C64*POWER(1/(1+Simulateur!$B$10),A64+0.5) -> 24135.073 | G64: =SUM(F64:F$64) -> 24135.073 | H64: =SUM(E64:E$64) -> 24553.805

Sheet Tables_CIMA
A1: TABLES DE MORTALITE REGLEMENTAIRES CIMA H ET CIMA F
A3: Age x | B3: l_x (H) | C3: d_x (H) | D3: q_x (H) | E3: Age x | F3: l_x (F) | G3: d_x (F) | H3: q_x (F)
A4: 20 | B4: 983382 | C4: 1549 | D4: 0.0015751763 | E4: 20 | F4: 991158 | G4: 829 | H4: 0.00083639541
A5: 21 | B5: 981833 | C5: 1612 | D5: 0.0016418271 | E5: 21 | F5: 990329 | G5: 857 | H5: 0.00086536898
A6: 22 | B6: 980221 | C6: 1665 | D6: 0.0016985965 | E6: 22 | F6: 989472 | G6: 895 | H6: 0.00090452282
A7: 23 | B7: 978556 | C7: 1720 | D7: 0.0017576919 | E7: 23 | F7: 988577 | G7: 885 | H7: 0.00089522617
A8: 24 | B8: 976836 | C8: 1574 | D8: 0.0016113247 | E8: 24 | F8: 987692 | G8: 902 | H8: 0.00091324016
A9: 25 | B9: 975262 | C9: 1771 | D9: 0.0018159223 | E9: 25 | F9: 986790 | G9: 930 | H9: 0.00094244976
A10: 26 | B10: 973491 | C10: 1803 | D10: 0.0018520972 | E10: 26 | F10: 985860 | G10: 978 | H10: 0.00099202727
A11: 27 | B11: 971688 | C11: 1841 | D11: 0.0018946411 | E11: 27 | F11: 984882 | G11: 1034 | H11: 0.001049872
A12: 28 | B12: 969847 | C12: 1888 | D12: 0.0019466988 | E12: 28 | F12: 983848 | G12: 966 | H12: 0.00098185899
A13: 29 | B13: 967959 | C13: 1678 | D13: 0.0017335445 | E13: 29 | F13: 982882 | G13: 995 | H13: 0.001012329
A14: 30 | B14: 966281 | C14: 1927 | D14: 0.0019942439 | E14: 30 | F14: 981887 | G14: 1056 | H14: 0.0010754802
A15: 31 | B15: 964354 | C15: 1964 | D15: 0.0020365965 | E15: 31 | F15: 980831 | G15: 1077 | H15: 0.0010980485
... A64: 80 | B64: 384899 | C64: 384899 | D64: 1 | E64: 80 | F64: 646754 | G64: 646754 | H64: 1
